Workbook

Sheet README
A1: Reserve Clinic — Driver-based financial model (proposed concept; prepared 2026-09-02)
A3: Purpose: illustrate the economics of a compliant premium consumer-health + telehealth + commerce model under three scenarios. Nothing here is a forecast of results; every number is an assumption or a formula on assumptions.
A4: How to use: edit BLUE cells on the Assumptions sheet only. Yellow-filled cells are the highest-sensitivity inputs and should be validated first (see Validation method column).
A5: Sheets: Scenario Summary (outputs) · Assumptions (inputs) · Assumptions Register (rationale) · Model_Conservative / Model_Base / Model_Upside (36 monthly columns) · Sensitivity (LTV:CAC, payback, price×churn grids) · Celebrity Economics (hypothetical partner structures).
A6: Color code: blue = input; black = formula; green = link to another sheet; yellow fill = key assumption.
A7: Structure caveats: prescription-program revenue is modeled as an all-in monthly program price. Whether the brand entity, the affiliated medical practice, or the pharmacy is merchant of record for medication depends on corporate-practice-of-medicine and fee-splitting analysis by counsel; revenue recognition may differ (e.g., management-fee model). Clinician prescribing rate is a clinical outcome that is monitored for safety, never targeted.
A8: Scenario A vs B: set 'Named-partner model active?' to 1 (Scenario A: brand-partner retainer, royalty and traffic uplift apply) or 0 (Scenario B: independent brand).
A9: Sources for benchmark-informed assumptions are summarized in 08_ReserveClinic_Evidence_Ledger.xlsx and research/06_market_size_benchmarks.md; each assumption's rationale is on the Assumptions sheet.
A10: This model is not investment, legal, medical, or tax advice.

Sheet Assumptions
A1: Reserve Clinic — Financial Model Assumptions (all values are FINANCIAL ASSUMPTIONS unless a source is cited)
A2: Blue = editable input. Three scenario columns drive Model_Conservative, Model_Base, Model_Upside. Change blue cells only; every other sheet recalculates. Prepared 2026-09-02; proposed concept.
A4: Key | B4: Assumption | C4: Unit | D4: Conservative | E4: Base | F4: Upside | G4: Rationale / source | H4: Confidence | I4: Sensitivity | J4: Validation method
A5: Timing
A6: launch_month | B6: Public launch month (model month #) | C6: month | D6: 9 | E6: 8 | F6: 7 | G6: Phase plan in 06_ReserveClinic_Launch_Plan.md: Phase 0-3 precede launch; conservative adds one month of slippage. | H6: Medium | I6: High | J6: Phase exit criteria
A7: beta_month | B7: Private beta start month | C7: month | D7: 6 | E7: 5 | F7: 5 | G7: Phase 2 begins after internal pilot. | H7: Medium | I7: Low | J7: Phase exit criteria
A8: Traffic
A9: organic_m1 | B9: Organic + direct sessions in month 1 | C9: sessions | D9: 1500 | E9: 2500 | F9: 4000 | G9: Prototype site with 20 library entries; comparable early-stage health content sites. Analyst assumption. | H9: Low | I9: Medium | J9: GA4 after month 1
A10: organic_growth | B10: Organic monthly growth rate | C10: % | D10: 0.07 | E10: 0.09 | F10: 0.11 | G10: Library-led SEO compounding; DTC health benchmarks show 8-15%/mo early growth from a small base (analyst inference from research/06 benchmarks). | H10: Low | I10: High | J10: Search Console trend, quarterly
A11: organic_cap | B11: Organic + direct sessions ceiling per month | C11: sessions | D11: 150000 | E11: 300000 | F11: 400000 | G11: Caps compounding growth; category-level informational search demand is finite (analyst inference). | H11: Low | I11: Medium | J11: Search Console
A12: cps | B12: Cost per paid session (blended) | C12: $ | D12: 2.3 | E12: 2 | F12: 1.8 | G12: Health/wellness CPC and CPM proxies; Meta health-category restrictions raise cost. Analyst assumption. | H12: Medium | I12: High | J12: Ad platform reports
A13: paid_pre | B13: Paid media spend per month, months 1 to beta-1 | C13: $ | D13: 10000 | E13: 20000 | F13: 30000 | G13: Waitlist/education ads only. | H13: Medium | I13: Low | J13: Budget actuals
A14: paid_beta | B14: Paid media spend per month, beta to launch-1 | C14: $ | D14: 30000 | E14: 60000 | F14: 100000 | G14: Waitlist building (Phase 3). | H14: Medium | I14: Medium | J14: Budget actuals
A15: paid_launch | B15: Paid media spend, launch month | C15: $ | D15: 200000 | E15: 350000 | F15: 500000 | G15: Phase 4 budget range. | H15: Medium | I15: Medium | J15: Budget actuals
A16: paid_post | B16: Paid media spend per month after launch (month launch+1) | C16: $ | D16: 100000 | E16: 180000 | F16: 250000 | G16: Phase 5 operating range; scaled by growth below. | H16: Medium | I16: High | J16: Payback discipline gate
A17: paid_growth | B17: Monthly growth in post-launch paid spend | C17: % | D17: 0.02 | E17: 0.03 | F17: 0.04 | G17: Spend grows only while payback <= target. | H17: Medium | I17: Medium | J17: Monthly CAC review
A18: Funnel (prescription programs)
A19: quiz_start | B19: Quiz start rate (starts / sessions) | C19: % | D19: 0.09 | E19: 0.1 | F19: 0.12 | G19: Telehealth quiz-start benchmarks 5-10% (analyst inference). | H19: Medium | I19: High | J19: Analytics
A20: quiz_complete | B20: Quiz completion rate | C20: % | D20: 0.6 | E20: 0.7 | F20: 0.75 | G20: One-question-per-screen quizzes typically 55-75%. | H20: Medium | I20: Medium | J20: Analytics
A21: eligible_outcome | B21: Share of completes with an eligible outcome | C21: % | D21: 0.5 | E21: 0.6 | F21: 0.65 | G21: Red-flag and state screening remove 40-55%. | H21: Medium | I21: Medium | J21: Analytics
A22: state_cov_launch | B22: Share of US population in served states at launch | C22: % | D22: 0.35 | E22: 0.4 | F22: 0.45 | G22: 4-6 pilot states incl. large states (TX, FL) if licensure achieved. | H22: Medium | I22: High | J22: State readiness tracker
A23: state_cov_step | B23: Monthly increase in population coverage after launch | C23: % | D23: 0.02 | E23: 0.03 | F23: 0.035 | G23: Tranche-based expansion. | H23: Medium | I23: Medium | J23: State readiness tracker
A24: state_cov_cap | B24: Maximum population coverage | C24: % | D24: 0.75 | E24: 0.85 | F24: 0.9 | G24: Some states excluded for CPOM/async restrictions. | H24: Medium | I24: Low | J24: Counsel memo
A25: intake_submit | B25: Intake submission rate (eligible → intake) | C25: % | D25: 0.48 | E25: 0.55 | F25: 0.6 | G25: ID verification and consent friction. | H25: Medium | I25: High | J25: Analytics
A26: consult_complete | B26: Consult completion rate | C26: % | D26: 0.75 | E26: 0.82 | F26: 0.88 | G26: Async review completes higher than video. | H26: Medium | I26: Medium | J26: EHR data
A27: rx_rate | B27: Clinician prescribing rate (clinical decision; not a target) | C27: % | D27: 0.55 | E27: 0.62 | F27: 0.68 | G27: Observed ranges for telehealth GLP-1/hormone programs 50-70% (third-party reports); monitored for safety only. | H27: Low | I27: High | J27: Medical director audit
A28: enroll_rate | B28: Enrollment (paid) rate after prescription | C28: % | D28: 0.58 | E28: 0.65 | F28: 0.68 | G28: Price shock at plan stage; all-in pricing shown earlier improves this. | H28: Medium | I28: High | J28: Analytics
A29: Pricing
A30: program_price | B30: All-in program price per member-month (blended) | C30: $ | D30: 249 | E30: 275 | F30: 299 | G30: Competitive bands in 03_Peptide_Product_and_Pricing_Audit.xlsx: compounded peptide programs ~$150-$450/mo; premium positioning. | H30: Medium | I30: High | J30: Van Westendorp + tests
A31: consult_fee | B31: Consultation fee (charged at intake) | C31: $ | D31: 49 | E31: 79 | F31: 99 | G31: Range $0-$150 among competitors; refundable if not eligible is common. | H31: Medium | I31: Medium | J31: Pricing test
A32: lab_attach | B32: Share of new intakes ordering labs | C32: % | D32: 0.4 | E32: 0.5 | F32: 0.6 | G32: Programs requiring labs (hormone/metabolic). | H32: Medium | I32: Medium | J32: EHR data
A33: lab_price | B33: Lab panel price charged | C33: $ | D33: 99 | E33: 119 | F33: 139 | G33: Direct-pay panels via lab partners. | H33: Medium | I33: Low | J33: Vendor quotes
A34: member_price | B34: Membership price per month (education, navigation, member pricing) | C34: $ | D34: 19 | E34: 29 | F34: 39 | G34: Function Health $499/yr, Superpower $199-499/yr and Lifeforce $129/mo bracket the range; Reserve Clinic tier is lighter. | H34: Medium | I34: Medium | J34: Pricing test
A35: member_attach_nonelig | B35: Membership attach among non-eligible quiz completers | C35: % | D35: 0.04 | E35: 0.06 | F35: 0.08 | G35: Analyst assumption. | H35: Low | I35: Medium | J35: Analytics
A36: member_attach_traffic | B36: Membership sign-ups per session (organic) | C36: % | D36: 0.0005 | E36: 0.001 | F36: 0.0015 | G36: Analyst assumption. | H36: Low | I36: Low | J36: Analytics
A37: shop_conv | B37: Non-Rx shop conversion (orders / sessions) | C37: % | D37: 0.006 | E37: 0.009 | F37: 0.012 | G37: DTC supplement conversion 0.5-1.5%. | H37: Medium | I37: Medium | J37: Shopify analytics
A38: shop_aov | B38: Non-Rx average order value | C38: $ | D38: 65 | E38: 75 | F38: 85 | G38: Premium supplement/cosmetic AOV. | H38: Medium | I38: Low | J38: Shopify analytics
A39: shop_repeat | B39: Monthly reorder rate of prior shop customers | C39: % | D39: 0.12 | E39: 0.15 | F39: 0.18 | G39: Subscription attach on consumables. | H39: Low | I39: Medium | J39: Shopify analytics
A40: Retention
A41: rx_churn | B41: Monthly churn, prescription programs (blended) | C41: % | D41: 0.13 | E41: 0.11 | F41: 0.1 | G41: DTC health subscription churn 8-15%/mo; GLP-1 programs higher. Third-party benchmarks in research/06. | H41: Low | I41: High | J41: Cohort analysis
...

Sheet Scenario Summary
A1: Reserve Clinic — Scenario summary (all cells link to model sheets; green = cross-sheet link)
A2: Proposed concept. Outputs are projections from labeled assumptions, not forecasts of results. Break-even = first month with positive EBITDA; capital required = most negative cumulative cash flow plus 15% contingency.
A4: Metric | B4: Unit | C4: Conservative | D4: Base | E4: Upside
A5: Year 1 net revenue | B5: $ | C5: =SUM(Model_Conservative!D43:O43) -> 443993.13 | D5: =SUM(Model_Base!D43:O43) -> 3428128.3 | E5: =SUM(Model_Upside!D43:O43) -> 14728834
A6: Year 2 net revenue | B6: $ | C6: =SUM(Model_Conservative!P43:AA43) -> 2517835.9 | D6: =SUM(Model_Base!P43:AA43) -> 19830860 | E6: =SUM(Model_Upside!P43:AA43) -> 83677545
A7: Year 3 net revenue | B7: $ | C7: =SUM(Model_Conservative!AB43:AM43) -> 5056214.6 | D7: =SUM(Model_Base!AB43:AM43) -> 42820608 | E7: =SUM(Model_Upside!AB43:AM43) -> 1.9417842e+08
A8: Year 1 gross profit | B8: $ | C8: =SUM(Model_Conservative!D54:O54) -> 147653.37 | D8: =SUM(Model_Base!D54:O54) -> 1717740.4 | E8: =SUM(Model_Upside!D54:O54) -> 8785277.8
A9: Year 2 gross profit | B9: $ | C9: =SUM(Model_Conservative!P54:AA54) -> 865047.33 | D9: =SUM(Model_Base!P54:AA54) -> 10009261 | E9: =SUM(Model_Upside!P54:AA54) -> 50035951
A10: Year 3 gross profit | B10: $ | C10: =SUM(Model_Conservative!AB54:AM54) -> 1738951 | D10: =SUM(Model_Base!AB54:AM54) -> 21570746 | E10: =SUM(Model_Upside!AB54:AM54) -> 1.1588844e+08
A11: Year 1 EBITDA | B11: $ | C11: =SUM(Model_Conservative!D77:O77) -> -2984706.4 | D11: =SUM(Model_Base!D77:O77) -> -3422156.3 | E11: =SUM(Model_Upside!D77:O77) -> 806332.09
A12: Year 2 EBITDA | B12: $ | C12: =SUM(Model_Conservative!P77:AA77) -> -4065789.4 | D12: =SUM(Model_Base!P77:AA77) -> 1043149.4 | E12: =SUM(Model_Upside!P77:AA77) -> 35215327
A13: Year 3 EBITDA | B13: $ | C13: =SUM(Model_Conservative!AB77:AM77) -> -4009826.1 | D13: =SUM(Model_Base!AB77:AM77) -> 9730800 | E13: =SUM(Model_Upside!AB77:AM77) -> 93685889
A14: Year 3 gross margin % | B14: % | C14: =IF(SUM(Model_Conservative!AB43:AM43)=0,0,SUM(Model_Conservative!AB54:AM54)/SUM(Model_Conservative!AB43:AM43)) -> 0.34392351 | D14: =IF(SUM(Model_Base!AB43:AM43)=0,0,SUM(Model_Base!AB54:AM54)/SUM(Model_Base!AB43:AM43)) -> 0.50374684 | E14: =IF(SUM(Model_Upside!AB43:AM43)=0,0,SUM(Model_Upside!AB54:AM54)/SUM(Model_Upside!AB43:AM43)) -> 0.59681419
A15: Active Rx members, month 12 | B15: # | C15: =Model_Conservative!O24 -> 229.05324 | D15: =Model_Base!O24 -> 1687.9488 | E15: =Model_Upside!O24 -> 6762.9762
A16: Active Rx members, month 24 | B16: # | C16: =Model_Conservative!AA24 -> 705.82123 | D16: =Model_Base!AA24 -> 6030.7692 | E16: =Model_Upside!AA24 -> 24843.633
A17: Active Rx members, month 36 | B17: # | C17: =Model_Conservative!AM24 -> 1302.8292 | D17: =Model_Base!AM24 -> 11437.582 | E17: =Model_Upside!AM24 -> 52299.684
A18: Active members (membership), month 36 | B18: # | C18: =Model_Conservative!AM29 -> 1595.8394 | D18: =Model_Base!AM29 -> 8289.8763 | E18: =Model_Upside!AM29 -> 27495.424
A19: Total sessions, 36 months | B19: # | C19: =Model_Conservative!C15 -> 1928704.1 | D19: =Model_Base!C15 -> 4900922.5 | E19: =Model_Upside!C15 -> 9779343.7
A20: Blended CAC, month 12 | B20: $ | C20: =Model_Conservative!O65 -> 268.39026 | D20: =Model_Base!O65 -> 137.51169 | E20: =Model_Upside!O65 -> 82.172491
A21: CAC per Rx member, month 12 | B21: $ | C21: =Model_Conservative!O66 -> 2003.1918 | D21: =Model_Base!O66 -> 584.03571 | E21: =Model_Upside!O66 -> 245.79703
A22: CAC per Rx member, month 24 | B22: $ | C22: =Model_Conservative!AA66 -> 1156.4848 | D22: =Model_Base!AA66 -> 312.62201 | E22: =Model_Upside!AA66 -> 139.24484
A23: Contribution per Rx member-month | B23: $ | C23: =Model_Conservative!O85 -> 84.582 | D23: =Model_Base!O85 -> 134.4 | E23: =Model_Upside!O85 -> 174.452
A24: LTV (contribution-based) | B24: $ | C24: =Model_Conservative!O86 -> 650.63077 | D24: =Model_Base!O86 -> 1221.8182 | E24: =Model_Upside!O86 -> 1744.52
A25: LTV : CAC, month 24 | B25: x | C25: =Model_Conservative!AA87 -> 0.56259347 | D25: =Model_Base!AA87 -> 3.9082923 | E25: =Model_Upside!AA87 -> 12.528435
A26: CAC payback, month 24 (months) | B26: months | C26: =Model_Conservative!AA88 -> 13.672942 | D26: =Model_Base!AA88 -> 2.3260566 | E26: =Model_Upside!AA88 -> 0.79818426
A27: Net revenue per active customer, month 36 | B27: $ | C27: =Model_Conservative!AM89 -> 181.046 | D27: =Model_Base!AM89 -> 232.11902 | E27: =Model_Upside!AM89 -> 275.67357
A28: Break-even month (first positive EBITDA) | B28: month | C28: =IF(MIN(Model_Conservative!D82:AM82)=999,"Not within 36 months",MIN(Model_Conservative!D82:AM82)) -> Not within 36 months | D28: =IF(MIN(Model_Base!D82:AM82)=999,"Not within 36 months",MIN(Model_Base!D82:AM82)) -> 18 | E28: =IF(MIN(Model_Upside!D82:AM82)=999,"Not within 36 months",MIN(Model_Upside!D82:AM82)) -> 8
A29: Peak cumulative cash burn | B29: $ | C29: =MIN(Model_Conservative!D80:AM80) -> -11189400 | D29: =MIN(Model_Base!D80:AM80) -> -4165450.1 | E29: =MIN(Model_Upside!D80:AM80) -> -2325279.2
A30: Capital required (peak burn + 15% contingency) | B30: $ | C30: =-MIN(Model_Conservative!D80:AM80)*1.15 -> 12867810 | D30: =-MIN(Model_Base!D80:AM80)*1.15 -> 4790267.6 | E30: =-MIN(Model_Upside!D80:AM80)*1.15 -> 2674071.1
A31: Cumulative cash flow, month 36 | B31: $ | C31: =Model_Conservative!AM80 -> -11189400 | D31: =Model_Base!AM80 -> 6911807.9 | E31: =Model_Upside!AM80 -> 1.283219e+08
A32: Brand partner cash + royalty paid, 36 months | B32: $ | C32: =-(Model_Conservative!C60+Model_Conservative!C61) -> 1015541.3 | D32: =-(Model_Base!C60+Model_Base!C61) -> 2942387.9 | E32: =-(Model_Upside!C60+Model_Upside!C61) -> 10057544

Sheet Model_Conservative
A1: Reserve Clinic monthly model — Conservative scenario (all cells are formulas driven by the Assumptions sheet)
A2: Units: $ unless noted. Month 1 = start of Phase 0. Prescription programs run through an affiliated medical practice and licensed pharmacies; revenue recognition and merchant-of-record structure subject to counsel.
A3: Line | B3: Unit | C3: 36-mo total | D3: 1 | E3: 2 | F3: 3 | G3: 4 | H3: 5 | I3: 6 | J3: 7 | K3: 8 | L3: 9 | M3: 10 | N3: 11 | O3: 12 | P3: 13 | Q3: 14 | R3: 15 | S3: 16 | T3: 17 | U3: 18 | V3: 19 | W3: 20 | X3: 21 | Y3: 22 | Z3: 23 | AA3: 24 | AB3: 25 | AC3: 26 | AD3: 27 | AE3: 28 | AF3: 29 | AG3: 30 | AH3: 31 | AI3: 32 | AJ3: 33 | AK3: 34 | AL3: 35 | AM3: 36
A4: Timing & coverage
A5: Model month | B5: # | D5: =D$3 -> 1 | E5: =E$3 -> 2 | F5: =F$3 -> 3 | G5: =G$3 -> 4 | H5: =H$3 -> 5 | I5: =I$3 -> 6 | J5: =J$3 -> 7 | K5: =K$3 -> 8 | ... AM5: =AM$3 -> 36
A6: Pre-beta phase flag | B6: flag | D6: =IF(D$3<Assumptions!$D$7,1,0) -> 1 | E6: =IF(E$3<Assumptions!$D$7,1,0) -> 1 | F6: =IF(F$3<Assumptions!$D$7,1,0) -> 1 | G6: =IF(G$3<Assumptions!$D$7,1,0) -> 1 | H6: =IF(H$3<Assumptions!$D$7,1,0) -> 1 | I6: =IF(I$3<Assumptions!$D$7,1,0) -> 0 | J6: =IF(J$3<Assumptions!$D$7,1,0) -> 0 | K6: =IF(K$3<Assumptions!$D$7,1,0) -> 0 | ... AM6: =IF(AM$3<Assumptions!$D$7,1,0) -> 0
A7: Beta/waitlist phase flag | B7: flag | D7: =IF(AND(D$3>=Assumptions!$D$7,D$3<Assumptions!$D$6),1,0) -> 0 | E7: =IF(AND(E$3>=Assumptions!$D$7,E$3<Assumptions!$D$6),1,0) -> 0 | F7: =IF(AND(F$3>=Assumptions!$D$7,F$3<Assumptions!$D$6),1,0) -> 0 | G7: =IF(AND(G$3>=Assumptions!$D$7,G$3<Assumptions!$D$6),1,0) -> 0 | H7: =IF(AND(H$3>=Assumptions!$D$7,H$3<Assumptions!$D$6),1,0) -> 0 | I7: =IF(AND(I$3>=Assumptions!$D$7,I$3<Assumptions!$D$6),1,0) -> 1 | J7: =IF(AND(J$3>=Assumptions!$D$7,J$3<Assumptions!$D$6),1,0) -> 1 | K7: =IF(AND(K$3>=Assumptions!$D$7,K$3<Assumptions!$D$6),1,0) -> 1 | ... AM7: =IF(AND(AM$3>=Assumptions!$D$7,AM$3<Assumptions!$D$6),1,0) -> 0
A8: Launch month flag | B8: flag | D8: =IF(D$3=Assumptions!$D$6,1,0) -> 0 | E8: =IF(E$3=Assumptions!$D$6,1,0) -> 0 | F8: =IF(F$3=Assumptions!$D$6,1,0) -> 0 | G8: =IF(G$3=Assumptions!$D$6,1,0) -> 0 | H8: =IF(H$3=Assumptions!$D$6,1,0) -> 0 | I8: =IF(I$3=Assumptions!$D$6,1,0) -> 0 | J8: =IF(J$3=Assumptions!$D$6,1,0) -> 0 | K8: =IF(K$3=Assumptions!$D$6,1,0) -> 0 | ... AM8: =IF(AM$3=Assumptions!$D$6,1,0) -> 0
A9: Post-launch flag (incl. launch month) | B9: flag | D9: =IF(D$3>=Assumptions!$D$6,1,0) -> 0 | E9: =IF(E$3>=Assumptions!$D$6,1,0) -> 0 | F9: =IF(F$3>=Assumptions!$D$6,1,0) -> 0 | G9: =IF(G$3>=Assumptions!$D$6,1,0) -> 0 | H9: =IF(H$3>=Assumptions!$D$6,1,0) -> 0 | I9: =IF(I$3>=Assumptions!$D$6,1,0) -> 0 | J9: =IF(J$3>=Assumptions!$D$6,1,0) -> 0 | K9: =IF(K$3>=Assumptions!$D$6,1,0) -> 0 | ... AM9: =IF(AM$3>=Assumptions!$D$6,1,0) -> 1
A10: Population coverage of served states (Rx) | B10: % | D10: =IF(D$3<Assumptions!$D$7,0,IF(D$3<Assumptions!$D$6,Assumptions!$D$22*0.5,MIN(Assumptions!$D$24,Assumptions!$D$22+Assumptions!$D$23*(D$3-Assumptions!$D$6)))) -> 0 | E10: =IF(E$3<Assumptions!$D$7,0,IF(E$3<Assumptions!$D$6,Assumptions!$D$22*0.5,MIN(Assumptions!$D$24,Assumptions!$D$22+Assumptions!$D$23*(E$3-Assumptions!$D$6)))) -> 0 | F10: =IF(F$3<Assumptions!$D$7,0,IF(F$3<Assumptions!$D$6,Assumptions!$D$22*0.5,MIN(Assumptions!$D$24,Assumptions!$D$22+Assumptions!$D$23*(F$3-Assumptions!$D$6)))) -> 0 | G10: =IF(G$3<Assumptions!$D$7,0,IF(G$3<Assumptions!$D$6,Assumptions!$D$22*0.5,MIN(Assumptions!$D$24,Assumptions!$D$22+Assumptions!$D$23*(G$3-Assumptions!$D$6)))) -> 0 | H10: =IF(H$3<Assumptions!$D$7,0,IF(H$3<Assumptions!$D$6,Assumptions!$D$22*0.5,MIN(Assumptions!$D$24,Assumptions!$D$22+Assumptions!$D$23*(H$3-Assumptions!$D$6)))) -> 0 | I10: =IF(I$3<Assumptions!$D$7,0,IF(I$3<Assumptions!$D$6,Assumptions!$D$22*0.5,MIN(Assumptions!$D$24,Assumptions!$D$22+Assumptions!$D$23*(I$3-Assumptions!$D$6)))) -> 0.175 | J10: =IF(J$3<Assumptions!$D$7,0,IF(J$3<Assumptions!$D$6,Assumptions!$D$22*0.5,MIN(Assumptions!$D$24,Assumptions!$D$22+Assumptions!$D$23*(J$3-Assumptions!$D$6)))) -> 0.175 | K10: =IF(K$3<Assumptions!$D$7,0,IF(K$3<Assumptions!$D$6,Assumptions!$D$22*0.5,MIN(Assumptions!$D$24,Assumptions!$D$22+Assumptions!$D$23*(K$3-Assumptions!$D$6)))) -> 0.175 | ... AM10: =IF(AM$3<Assumptions!$D$7,0,IF(AM$3<Assumptions!$D$6,Assumptions!$D$22*0.5,MIN(Assumptions!$D$24,Assumptions!$D$22+Assumptions!$D$23*(AM$3-Assumptions!$D$6)))) -> 0.75
A11: Traffic
A12: Paid media spend | B12: $ | C12: =SUM(D12:AM12) -> 3874432.4 | D12: =IF(D$3<Assumptions!$D$7,Assumptions!$D$13,IF(D$3<Assumptions!$D$6,Assumptions!$D$14,IF(D$3=Assumptions!$D$6,Assumptions!$D$15,Assumptions!$D$16*(1+Assumptions!$D$17)^(D$3-Assumptions!$D$6-1)))) -> 10000 | E12: =IF(E$3<Assumptions!$D$7,Assumptions!$D$13,IF(E$3<Assumptions!$D$6,Assumptions!$D$14,IF(E$3=Assumptions!$D$6,Assumptions!$D$15,Assumptions!$D$16*(1+Assumptions!$D$17)^(E$3-Assumptions!$D$6-1)))) -> 10000 | F12: =IF(F$3<Assumptions!$D$7,Assumptions!$D$13,IF(F$3<Assumptions!$D$6,Assumptions!$D$14,IF(F$3=Assumptions!$D$6,Assumptions!$D$15,Assumptions!$D$16*(1+Assumptions!$D$17)^(F$3-Assumptions!$D$6-1)))) -> 10000 | G12: =IF(G$3<Assumptions!$D$7,Assumptions!$D$13,IF(G$3<Assumptions!$D$6,Assumptions!$D$14,IF(G$3=Assumptions!$D$6,Assumptions!$D$15,Assumptions!$D$16*(1+Assumptions!$D$17)^(G$3-Assumptions!$D$6-1)))) -> 10000 | H12: =IF(H$3<Assumptions!$D$7,Assumptions!$D$13,IF(H$3<Assumptions!$D$6,Assumptions!$D$14,IF(H$3=Assumptions!$D$6,Assumptions!$D$15,Assumptions!$D$16*(1+Assumptions!$D$17)^(H$3-Assumptions!$D$6-1)))) -> 10000 | I12: =IF(I$3<Assumptions!$D$7,Assumptions!$D$13,IF(I$3<Assumptions!$D$6,Assumptions!$D$14,IF(I$3=Assumptions!$D$6,Assumptions!$D$15,Assumptions!$D$16*(1+Assumptions!$D$17)^(I$3-Assumptions!$D$6-1)))) -> 30000 | J12: =IF(J$3<Assumptions!$D$7,Assumptions!$D$13,IF(J$3<Assumptions!$D$6,Assumptions!$D$14,IF(J$3=Assumptions!$D$6,Assumptions!$D$15,Assumptions!$D$16*(1+Assumptions!$D$17)^(J$3-Assumptions!$D$6-1)))) -> 30000 | K12: =IF(K$3<Assumptions!$D$7,Assumptions!$D$13,IF(K$3<Assumptions!$D$6,Assumptions!$D$14,IF(K$3=Assumptions!$D$6,Assumptions!$D$15,Assumptions!$D$16*(1+Assumptions!$D$17)^(K$3-Assumptions!$D$6-1)))) -> 30000 | ... AM12: =IF(AM$3<Assumptions!$D$7,Assumptions!$D$13,IF(AM$3<Assumptions!$D$6,Assumptions!$D$14,IF(AM$3=Assumptions!$D$6,Assumptions!$D$15,Assumptions!$D$16*(1+Assumptions!$D$17)^(AM$3-Assumptions!$D$6-1)))) -> 167341.81
A13: Paid sessions | B13: sessions | C13: =SUM(D13:AM13) -> 1684535.8 | D13: =D12/Assumptions!$D$12 -> 4347.8261 | E13: =E12/Assumptions!$D$12 -> 4347.8261 | F13: =F12/Assumptions!$D$12 -> 4347.8261 | G13: =G12/Assumptions!$D$12 -> 4347.8261 | H13: =H12/Assumptions!$D$12 -> 4347.8261 | I13: =I12/Assumptions!$D$12 -> 13043.478 | J13: =J12/Assumptions!$D$12 -> 13043.478 | K13: =K12/Assumptions!$D$12 -> 13043.478 | ... AM13: =AM12/Assumptions!$D$12 -> 72757.309
A14: Organic + direct sessions | B14: sessions | C14: =SUM(D14:AM14) -> 244168.24 | D14: =MIN(Assumptions!$D$11,Assumptions!$D$9*(1+Assumptions!$D$10)^(D$3-1))*IF(AND(D9=1,Assumptions!$D$74=1),Assumptions!$D$78,1) -> 1500 | E14: =MIN(Assumptions!$D$11,Assumptions!$D$9*(1+Assumptions!$D$10)^(E$3-1))*IF(AND(E9=1,Assumptions!$D$74=1),Assumptions!$D$78,1) -> 1605 | F14: =MIN(Assumptions!$D$11,Assumptions!$D$9*(1+Assumptions!$D$10)^(F$3-1))*IF(AND(F9=1,Assumptions!$D$74=1),Assumptions!$D$78,1) -> 1717.35 | G14: =MIN(Assumptions!$D$11,Assumptions!$D$9*(1+Assumptions!$D$10)^(G$3-1))*IF(AND(G9=1,Assumptions!$D$74=1),Assumptions!$D$78,1) -> 1837.5645 | H14: =MIN(Assumptions!$D$11,Assumptions!$D$9*(1+Assumptions!$D$10)^(H$3-1))*IF(AND(H9=1,Assumptions!$D$74=1),Assumptions!$D$78,1) -> 1966.194 | I14: =MIN(Assumptions!$D$11,Assumptions!$D$9*(1+Assumptions!$D$10)^(I$3-1))*IF(AND(I9=1,Assumptions!$D$74=1),Assumptions!$D$78,1) -> 2103.8276 | J14: =MIN(Assumptions!$D$11,Assumptions!$D$9*(1+Assumptions!$D$10)^(J$3-1))*IF(AND(J9=1,Assumptions!$D$74=1),Assumptions!$D$78,1) -> 2251.0955 | K14: =MIN(Assumptions!$D$11,Assumptions!$D$9*(1+Assumptions!$D$10)^(K$3-1))*IF(AND(K9=1,Assumptions!$D$74=1),Assumptions!$D$78,1) -> 2408.6722 | ... AM14: =MIN(Assumptions!$D$11,Assumptions!$D$9*(1+Assumptions!$D$10)^(AM$3-1))*IF(AND(AM9=1,Assumptions!$D$74=1),Assumptions!$D$78,1) -> 17616.359
A15: Total sessions | B15: sessions | C15: =SUM(D15:AM15) -> 1928704.1 | D15: =D13+D14 -> 5847.8261 | E15: =E13+E14 -> 5952.8261 | F15: =F13+F14 -> 6065.1761 | G15: =G13+G14 -> 6185.3906 | H15: =H13+H14 -> 6314.0201 | I15: =I13+I14 -> 15147.306 | J15: =J13+J14 -> 15294.574 | K15: =K13+K14 -> 15452.15 | ... AM15: =AM13+AM14 -> 90373.669
A16: Prescription-program funnel (clinical decisions are independent; rates are monitored, not targeted)
A17: Eligibility quiz starts | B17: # | C17: =SUM(D17:AM17) -> 170850.49 | D17: =D15*Assumptions!$D$19*IF(D$3<Assumptions!$D$7,0,1) -> 0 | E17: =E15*Assumptions!$D$19*IF(E$3<Assumptions!$D$7,0,1) -> 0 | F17: =F15*Assumptions!$D$19*IF(F$3<Assumptions!$D$7,0,1) -> 0 | G17: =G15*Assumptions!$D$19*IF(G$3<Assumptions!$D$7,0,1) -> 0 | H17: =H15*Assumptions!$D$19*IF(H$3<Assumptions!$D$7,0,1) -> 0 | I17: =I15*Assumptions!$D$19*IF(I$3<Assumptions!$D$7,0,1) -> 1363.2575 | J17: =J15*Assumptions!$D$19*IF(J$3<Assumptions!$D$7,0,1) -> 1376.5116 | K17: =K15*Assumptions!$D$19*IF(K$3<Assumptions!$D$7,0,1) -> 1390.6935 | ... AM17: =AM15*Assumptions!$D$19*IF(AM$3<Assumptions!$D$7,0,1) -> 8133.6302
A18: Quiz completions | B18: # | C18: =SUM(D18:AM18) -> 102510.3 | D18: =D17*Assumptions!$D$20 -> 0 | E18: =E17*Assumptions!$D$20 -> 0 | F18: =F17*Assumptions!$D$20 -> 0 | G18: =G17*Assumptions!$D$20 -> 0 | H18: =H17*Assumptions!$D$20 -> 0 | I18: =I17*Assumptions!$D$20 -> 817.95452 | J18: =J17*Assumptions!$D$20 -> 825.90698 | K18: =K17*Assumptions!$D$20 -> 834.41613 | ... AM18: =AM17*Assumptions!$D$20 -> 4880.1781
A19: Eligible outcomes (screen + state) | B19: # | C19: =SUM(D19:AM19) -> 31223.055 | D19: =D18*Assumptions!$D$21*D10 -> 0 | E19: =E18*Assumptions!$D$21*E10 -> 0 | F19: =F18*Assumptions!$D$21*F10 -> 0 | G19: =G18*Assumptions!$D$21*G10 -> 0 | H19: =H18*Assumptions!$D$21*H10 -> 0 | I19: =I18*Assumptions!$D$21*I10 -> 71.57102 | J19: =J18*Assumptions!$D$21*J10 -> 72.266861 | K19: =K18*Assumptions!$D$21*K10 -> 73.011411 | ... AM19: =AM18*Assumptions!$D$21*AM10 -> 1830.0668
A20: Intakes submitted (consult fee charged) | B20: # | C20: =SUM(D20:AM20) -> 14987.066 | D20: =D19*Assumptions!$D$25 -> 0 | E20: =E19*Assumptions!$D$25 -> 0 | F20: =F19*Assumptions!$D$25 -> 0 | G20: =G19*Assumptions!$D$25 -> 0 | H20: =H19*Assumptions!$D$25 -> 0 | I20: =I19*Assumptions!$D$25 -> 34.35409 | J20: =J19*Assumptions!$D$25 -> 34.688093 | K20: =K19*Assumptions!$D$25 -> 35.045477 | ... AM20: =AM19*Assumptions!$D$25 -> 878.43206
A21: Consults completed | B21: # | C21: =SUM(D21:AM21) -> 11240.3 | D21: =D20*Assumptions!$D$26 -> 0 | E21: =E20*Assumptions!$D$26 -> 0 | F21: =F20*Assumptions!$D$26 -> 0 | G21: =G20*Assumptions!$D$26 -> 0 | H21: =H20*Assumptions!$D$26 -> 0 | I21: =I20*Assumptions!$D$26 -> 25.765567 | J21: =J20*Assumptions!$D$26 -> 26.01607 | K21: =K20*Assumptions!$D$26 -> 26.284108 | ... AM21: =AM20*Assumptions!$D$26 -> 658.82405
A22: Prescriptions issued (clinician decision) | B22: # | C22: =SUM(D22:AM22) -> 6182.1648 | D22: =D21*Assumptions!$D$27 -> 0 | E22: =E21*Assumptions!$D$27 -> 0 | F22: =F21*Assumptions!$D$27 -> 0 | G22: =G21*Assumptions!$D$27 -> 0 | H22: =H21*Assumptions!$D$27 -> 0 | I22: =I21*Assumptions!$D$27 -> 14.171062 | J22: =J21*Assumptions!$D$27 -> 14.308839 | K22: =K21*Assumptions!$D$27 -> 14.456259 | ... AM22: =AM21*Assumptions!$D$27 -> 362.35322
A23: New paying Rx program members | B23: # | C23: =SUM(D23:AM23) -> 3585.6556 | D23: =D22*Assumptions!$D$28 -> 0 | E23: =E22*Assumptions!$D$28 -> 0 | F23: =F22*Assumptions!$D$28 -> 0 | G23: =G22*Assumptions!$D$28 -> 0 | H23: =H22*Assumptions!$D$28 -> 0 | I23: =I22*Assumptions!$D$28 -> 8.219216 | J23: =J22*Assumptions!$D$28 -> 8.2991263 | K23: =K22*Assumptions!$D$28 -> 8.3846304 | ... AM23: =AM22*Assumptions!$D$28 -> 210.16487
A24: Active Rx program members (end of month) | B24: # | D24: =D23 -> 0 | E24: =D24*(1-Assumptions!$D$41)+E23 -> 0 | F24: =E24*(1-Assumptions!$D$41)+F23 -> 0 | G24: =F24*(1-Assumptions!$D$41)+G23 -> 0 | H24: =G24*(1-Assumptions!$D$41)+H23 -> 0 | I24: =H24*(1-Assumptions!$D$41)+I23 -> 8.219216 | J24: =I24*(1-Assumptions!$D$41)+J23 -> 15.449844 | K24: =J24*(1-Assumptions!$D$41)+K23 -> 21.825995 | L24: =K24*(1-Assumptions!$D$41)+L23 -> 116.43379 | ... AM24: =AL24*(1-Assumptions!$D$41)+AM23 -> 1302.8292
A25: Rx members churned | B25: # | C25: =SUM(D25:AM25) -> 2282.8264 | D25: =0 -> 0 | E25: =D24*Assumptions!$D$41 -> 0 | F25: =E24*Assumptions!$D$41 -> 0 | G25: =F24*Assumptions!$D$41 -> 0 | H25: =G24*Assumptions!$D$41 -> 0 | I25: =H24*Assumptions!$D$41 -> 0 | J25: =I24*Assumptions!$D$41 -> 1.0684981 | K25: =J24*Assumptions!$D$41 -> 2.0084797 | L25: =K24*Assumptions!$D$41 -> 2.8373793 | ... AM25: =AL24*Assumptions!$D$41 -> 163.27168
A26: Lab panels ordered | B26: # | C26: =SUM(D26:AM26) -> 5994.8265 | D26: =D20*Assumptions!$D$32 -> 0 | E26: =E20*Assumptions!$D$32 -> 0 | F26: =F20*Assumptions!$D$32 -> 0 | G26: =G20*Assumptions!$D$32 -> 0 | H26: =H20*Assumptions!$D$32 -> 0 | I26: =I20*Assumptions!$D$32 -> 13.741636 | J26: =J20*Assumptions!$D$32 -> 13.875237 | K26: =K20*Assumptions!$D$32 -> 14.018191 | ... AM26: =AM20*Assumptions!$D$32 -> 351.37282
A27: Membership and non-prescription commerce
A28: New membership sign-ups | B28: # | C28: =SUM(D28:AM28) -> 3800.6591 | D28: =(D18-D19)*Assumptions!$D$35+D15*Assumptions!$D$36*IF(D$3<Assumptions!$D$7,0,1) -> 0 | E28: =(E18-E19)*Assumptions!$D$35+E15*Assumptions!$D$36*IF(E$3<Assumptions!$D$7,0,1) -> 0 | F28: =(F18-F19)*Assumptions!$D$35+F15*Assumptions!$D$36*IF(F$3<Assumptions!$D$7,0,1) -> 0 | G28: =(G18-G19)*Assumptions!$D$35+G15*Assumptions!$D$36*IF(G$3<Assumptions!$D$7,0,1) -> 0 | H28: =(H18-H19)*Assumptions!$D$35+H15*Assumptions!$D$36*IF(H$3<Assumptions!$D$7,0,1) -> 0 | I28: =(I18-I19)*Assumptions!$D$35+I15*Assumptions!$D$36*IF(I$3<Assumptions!$D$7,0,1) -> 37.428993 | J28: =(J18-J19)*Assumptions!$D$35+J15*Assumptions!$D$36*IF(J$3<Assumptions!$D$7,0,1) -> 37.792892 | K28: =(K18-K19)*Assumptions!$D$35+K15*Assumptions!$D$36*IF(K$3<Assumptions!$D$7,0,1) -> 38.182264 | ... AM28: =(AM18-AM19)*Assumptions!$D$35+AM15*Assumptions!$D$36*IF(AM$3<Assumptions!$D$7,0,1) -> 167.19129
A29: Active members (end of month) | B29: # | D29: =D28 -> 0 | E29: =D29*(1-Assumptions!$D$42)+E28 -> 0 | F29: =E29*(1-Assumptions!$D$42)+F28 -> 0 | G29: =F29*(1-Assumptions!$D$42)+G28 -> 0 | H29: =G29*(1-Assumptions!$D$42)+H28 -> 0 | I29: =H29*(1-Assumptions!$D$42)+I28 -> 37.428993 | J29: =I29*(1-Assumptions!$D$42)+J28 -> 72.227565 | K29: =J29*(1-Assumptions!$D$42)+K28 -> 104.63162 | L29: =K29*(1-Assumptions!$D$42)+L28 -> 301.16536 | ... AM29: =AL29*(1-Assumptions!$D$42)+AM28 -> 1595.8394
A30: Members churned | B30: # | C30: =SUM(D30:AM30) -> 2204.8196 | D30: =0 -> 0 | E30: =D29*Assumptions!$D$42 -> 0 | F30: =E29*Assumptions!$D$42 -> 0 | G30: =F29*Assumptions!$D$42 -> 0 | H30: =G29*Assumptions!$D$42 -> 0 | I30: =H29*Assumptions!$D$42 -> 0 | J30: =I29*Assumptions!$D$42 -> 2.9943194 | K30: =J29*Assumptions!$D$42 -> 5.7782052 | L30: =K29*Assumptions!$D$42 -> 8.3705299 | ... AM30: =AL29*Assumptions!$D$42 -> 124.23027
A31: Non-Rx first orders | B31: # | C31: =SUM(D31:AM31) -> 11390.033 | D31: =D15*Assumptions!$D$37*IF(D$3<Assumptions!$D$7,0,1) -> 0 | E31: =E15*Assumptions!$D$37*IF(E$3<Assumptions!$D$7,0,1) -> 0 | F31: =F15*Assumptions!$D$37*IF(F$3<Assumptions!$D$7,0,1) -> 0 | G31: =G15*Assumptions!$D$37*IF(G$3<Assumptions!$D$7,0,1) -> 0 | H31: =H15*Assumptions!$D$37*IF(H$3<Assumptions!$D$7,0,1) -> 0 | I31: =I15*Assumptions!$D$37*IF(I$3<Assumptions!$D$7,0,1) -> 90.883835 | J31: =J15*Assumptions!$D$37*IF(J$3<Assumptions!$D$7,0,1) -> 91.767443 | K31: =K15*Assumptions!$D$37*IF(K$3<Assumptions!$D$7,0,1) -> 92.712903 | ... AM31: =AM15*Assumptions!$D$37*IF(AM$3<Assumptions!$D$7,0,1) -> 542.24201
A32: Cumulative non-Rx customers | B32: # | D32: =D31 -> 0 | E32: =D32+E31 -> 0 | F32: =E32+F31 -> 0 | G32: =F32+G31 -> 0 | H32: =G32+H31 -> 0 | I32: =H32+I31 -> 90.883835 | J32: =I32+J31 -> 182.65128 | K32: =J32+K31 -> 275.36418 | L32: =K32+L31 -> 814.11335 | ... AM32: =AL32+AM31 -> 11390.033
A33: Non-Rx repeat orders | B33: # | C33: =SUM(D33:AM33) -> 17245.832 | D33: =0 -> 0 | E33: =D32*Assumptions!$D$39 -> 0 | F33: =E32*Assumptions!$D$39 -> 0 | G33: =F32*Assumptions!$D$39 -> 0 | H33: =G32*Assumptions!$D$39 -> 0 | I33: =H32*Assumptions!$D$39 -> 0 | J33: =I32*Assumptions!$D$39 -> 10.90606 | K33: =J32*Assumptions!$D$39 -> 21.918153 | L33: =K32*Assumptions!$D$39 -> 33.043702 | ... AM33: =AL32*Assumptions!$D$39 -> 1301.7349
A34: Total non-Rx orders | B34: # | C34: =SUM(D34:AM34) -> 28635.865 | D34: =D31+D33 -> 0 | E34: =E31+E33 -> 0 | F34: =F31+F33 -> 0 | G34: =G31+G33 -> 0 | H34: =H31+H33 -> 0 | I34: =I31+I33 -> 90.883835 | J34: =J31+J33 -> 102.6735 | K34: =K31+K33 -> 114.63106 | ... AM34: =AM31+AM33 -> 1843.9769
A35: Revenue
A36: Rx program revenue (all-in monthly) | B36: $ | C36: =SUM(D36:AM36) -> 4696895 | D36: =D24*Assumptions!$D$30 -> 0 | E36: =E24*Assumptions!$D$30 -> 0 | F36: =F24*Assumptions!$D$30 -> 0 | G36: =G24*Assumptions!$D$30 -> 0 | H36: =H24*Assumptions!$D$30 -> 0 | I36: =I24*Assumptions!$D$30 -> 2046.5848 | J36: =J24*Assumptions!$D$30 -> 3847.0112 | K36: =K24*Assumptions!$D$30 -> 5434.6727 | ... AM36: =AM24*Assumptions!$D$30 -> 324404.47
A37: Consultation revenue | B37: $ | C37: =SUM(D37:AM37) -> 734366.24 | D37: =D20*Assumptions!$D$31 -> 0 | E37: =E20*Assumptions!$D$31 -> 0 | F37: =F20*Assumptions!$D$31 -> 0 | G37: =G20*Assumptions!$D$31 -> 0 | H37: =H20*Assumptions!$D$31 -> 0 | I37: =I20*Assumptions!$D$31 -> 1683.3504 | J37: =J20*Assumptions!$D$31 -> 1699.7166 | K37: =K20*Assumptions!$D$31 -> 1717.2284 | ... AM37: =AM20*Assumptions!$D$31 -> 43043.171
A38: Lab revenue | B38: $ | C38: =SUM(D38:AM38) -> 593487.82 | D38: =D26*Assumptions!$D$33 -> 0 | E38: =E26*Assumptions!$D$33 -> 0 | F38: =F26*Assumptions!$D$33 -> 0 | G38: =G26*Assumptions!$D$33 -> 0 | H38: =H26*Assumptions!$D$33 -> 0 | I38: =I26*Assumptions!$D$33 -> 1360.422 | J38: =J26*Assumptions!$D$33 -> 1373.6485 | K38: =K26*Assumptions!$D$33 -> 1387.8009 | ... AM38: =AM26*Assumptions!$D$33 -> 34785.91
A39: Membership revenue | B39: $ | C39: =SUM(D39:AM39) -> 553965.61 | D39: =D29*Assumptions!$D$34 -> 0 | E39: =E29*Assumptions!$D$34 -> 0 | F39: =F29*Assumptions!$D$34 -> 0 | G39: =G29*Assumptions!$D$34 -> 0 | H39: =H29*Assumptions!$D$34 -> 0 | I39: =I29*Assumptions!$D$34 -> 711.15086 | J39: =J29*Assumptions!$D$34 -> 1372.3237 | K39: =K29*Assumptions!$D$34 -> 1988.0009 | ... AM39: =AM29*Assumptions!$D$34 -> 30320.949
A40: Non-Rx commerce revenue | B40: $ | C40: =SUM(D40:AM40) -> 1861331.2 | D40: =D34*Assumptions!$D$38 -> 0 | E40: =E34*Assumptions!$D$38 -> 0 | F40: =F34*Assumptions!$D$38 -> 0 | G40: =G34*Assumptions!$D$38 -> 0 | H40: =H34*Assumptions!$D$38 -> 0 | I40: =I34*Assumptions!$D$38 -> 5907.4493 | J40: =J34*Assumptions!$D$38 -> 6673.7777 | K40: =K34*Assumptions!$D$38 -> 7451.0187 | ... AM40: =AM34*Assumptions!$D$38 -> 119858.5
...

Sheet Model_Base
A1: Reserve Clinic monthly model — Base scenario (all cells are formulas driven by the Assumptions sheet)
A2: Units: $ unless noted. Month 1 = start of Phase 0. Prescription programs run through an affiliated medical practice and licensed pharmacies; revenue recognition and merchant-of-record structure subject to counsel.
A3: Line | B3: Unit | C3: 36-mo total | D3: 1 | E3: 2 | F3: 3 | G3: 4 | H3: 5 | I3: 6 | J3: 7 | K3: 8 | L3: 9 | M3: 10 | N3: 11 | O3: 12 | P3: 13 | Q3: 14 | R3: 15 | S3: 16 | T3: 17 | U3: 18 | V3: 19 | W3: 20 | X3: 21 | Y3: 22 | Z3: 23 | AA3: 24 | AB3: 25 | AC3: 26 | AD3: 27 | AE3: 28 | AF3: 29 | AG3: 30 | AH3: 31 | AI3: 32 | AJ3: 33 | AK3: 34 | AL3: 35 | AM3: 36
A4: Timing & coverage
A5: Model month | B5: # | D5: =D$3 -> 1 | E5: =E$3 -> 2 | F5: =F$3 -> 3 | G5: =G$3 -> 4 | H5: =H$3 -> 5 | I5: =I$3 -> 6 | J5: =J$3 -> 7 | K5: =K$3 -> 8 | ... AM5: =AM$3 -> 36
A6: Pre-beta phase flag | B6: flag | D6: =IF(D$3<Assumptions!$E$7,1,0) -> 1 | E6: =IF(E$3<Assumptions!$E$7,1,0) -> 1 | F6: =IF(F$3<Assumptions!$E$7,1,0) -> 1 | G6: =IF(G$3<Assumptions!$E$7,1,0) -> 1 | H6: =IF(H$3<Assumptions!$E$7,1,0) -> 0 | I6: =IF(I$3<Assumptions!$E$7,1,0) -> 0 | J6: =IF(J$3<Assumptions!$E$7,1,0) -> 0 | K6: =IF(K$3<Assumptions!$E$7,1,0) -> 0 | ... AM6: =IF(AM$3<Assumptions!$E$7,1,0) -> 0
A7: Beta/waitlist phase flag | B7: flag | D7: =IF(AND(D$3>=Assumptions!$E$7,D$3<Assumptions!$E$6),1,0) -> 0 | E7: =IF(AND(E$3>=Assumptions!$E$7,E$3<Assumptions!$E$6),1,0) -> 0 | F7: =IF(AND(F$3>=Assumptions!$E$7,F$3<Assumptions!$E$6),1,0) -> 0 | G7: =IF(AND(G$3>=Assumptions!$E$7,G$3<Assumptions!$E$6),1,0) -> 0 | H7: =IF(AND(H$3>=Assumptions!$E$7,H$3<Assumptions!$E$6),1,0) -> 1 | I7: =IF(AND(I$3>=Assumptions!$E$7,I$3<Assumptions!$E$6),1,0) -> 1 | J7: =IF(AND(J$3>=Assumptions!$E$7,J$3<Assumptions!$E$6),1,0) -> 1 | K7: =IF(AND(K$3>=Assumptions!$E$7,K$3<Assumptions!$E$6),1,0) -> 0 | ... AM7: =IF(AND(AM$3>=Assumptions!$E$7,AM$3<Assumptions!$E$6),1,0) -> 0
A8: Launch month flag | B8: flag | D8: =IF(D$3=Assumptions!$E$6,1,0) -> 0 | E8: =IF(E$3=Assumptions!$E$6,1,0) -> 0 | F8: =IF(F$3=Assumptions!$E$6,1,0) -> 0 | G8: =IF(G$3=Assumptions!$E$6,1,0) -> 0 | H8: =IF(H$3=Assumptions!$E$6,1,0) -> 0 | I8: =IF(I$3=Assumptions!$E$6,1,0) -> 0 | J8: =IF(J$3=Assumptions!$E$6,1,0) -> 0 | K8: =IF(K$3=Assumptions!$E$6,1,0) -> 1 | ... AM8: =IF(AM$3=Assumptions!$E$6,1,0) -> 0
A9: Post-launch flag (incl. launch month) | B9: flag | D9: =IF(D$3>=Assumptions!$E$6,1,0) -> 0 | E9: =IF(E$3>=Assumptions!$E$6,1,0) -> 0 | F9: =IF(F$3>=Assumptions!$E$6,1,0) -> 0 | G9: =IF(G$3>=Assumptions!$E$6,1,0) -> 0 | H9: =IF(H$3>=Assumptions!$E$6,1,0) -> 0 | I9: =IF(I$3>=Assumptions!$E$6,1,0) -> 0 | J9: =IF(J$3>=Assumptions!$E$6,1,0) -> 0 | K9: =IF(K$3>=Assumptions!$E$6,1,0) -> 1 | ... AM9: =IF(AM$3>=Assumptions!$E$6,1,0) -> 1
A10: Population coverage of served states (Rx) | B10: % | D10: =IF(D$3<Assumptions!$E$7,0,IF(D$3<Assumptions!$E$6,Assumptions!$E$22*0.5,MIN(Assumptions!$E$24,Assumptions!$E$22+Assumptions!$E$23*(D$3-Assumptions!$E$6)))) -> 0 | E10: =IF(E$3<Assumptions!$E$7,0,IF(E$3<Assumptions!$E$6,Assumptions!$E$22*0.5,MIN(Assumptions!$E$24,Assumptions!$E$22+Assumptions!$E$23*(E$3-Assumptions!$E$6)))) -> 0 | F10: =IF(F$3<Assumptions!$E$7,0,IF(F$3<Assumptions!$E$6,Assumptions!$E$22*0.5,MIN(Assumptions!$E$24,Assumptions!$E$22+Assumptions!$E$23*(F$3-Assumptions!$E$6)))) -> 0 | G10: =IF(G$3<Assumptions!$E$7,0,IF(G$3<Assumptions!$E$6,Assumptions!$E$22*0.5,MIN(Assumptions!$E$24,Assumptions!$E$22+Assumptions!$E$23*(G$3-Assumptions!$E$6)))) -> 0 | H10: =IF(H$3<Assumptions!$E$7,0,IF(H$3<Assumptions!$E$6,Assumptions!$E$22*0.5,MIN(Assumptions!$E$24,Assumptions!$E$22+Assumptions!$E$23*(H$3-Assumptions!$E$6)))) -> 0.2 | I10: =IF(I$3<Assumptions!$E$7,0,IF(I$3<Assumptions!$E$6,Assumptions!$E$22*0.5,MIN(Assumptions!$E$24,Assumptions!$E$22+Assumptions!$E$23*(I$3-Assumptions!$E$6)))) -> 0.2 | J10: =IF(J$3<Assumptions!$E$7,0,IF(J$3<Assumptions!$E$6,Assumptions!$E$22*0.5,MIN(Assumptions!$E$24,Assumptions!$E$22+Assumptions!$E$23*(J$3-Assumptions!$E$6)))) -> 0.2 | K10: =IF(K$3<Assumptions!$E$7,0,IF(K$3<Assumptions!$E$6,Assumptions!$E$22*0.5,MIN(Assumptions!$E$24,Assumptions!$E$22+Assumptions!$E$23*(K$3-Assumptions!$E$6)))) -> 0.4 | ... AM10: =IF(AM$3<Assumptions!$E$7,0,IF(AM$3<Assumptions!$E$6,Assumptions!$E$22*0.5,MIN(Assumptions!$E$24,Assumptions!$E$22+Assumptions!$E$23*(AM$3-Assumptions!$E$6)))) -> 0.85
A11: Traffic
A12: Paid media spend | B12: $ | C12: =SUM(D12:AM12) -> 8337566.1 | D12: =IF(D$3<Assumptions!$E$7,Assumptions!$E$13,IF(D$3<Assumptions!$E$6,Assumptions!$E$14,IF(D$3=Assumptions!$E$6,Assumptions!$E$15,Assumptions!$E$16*(1+Assumptions!$E$17)^(D$3-Assumptions!$E$6-1)))) -> 20000 | E12: =IF(E$3<Assumptions!$E$7,Assumptions!$E$13,IF(E$3<Assumptions!$E$6,Assumptions!$E$14,IF(E$3=Assumptions!$E$6,Assumptions!$E$15,Assumptions!$E$16*(1+Assumptions!$E$17)^(E$3-Assumptions!$E$6-1)))) -> 20000 | F12: =IF(F$3<Assumptions!$E$7,Assumptions!$E$13,IF(F$3<Assumptions!$E$6,Assumptions!$E$14,IF(F$3=Assumptions!$E$6,Assumptions!$E$15,Assumptions!$E$16*(1+Assumptions!$E$17)^(F$3-Assumptions!$E$6-1)))) -> 20000 | G12: =IF(G$3<Assumptions!$E$7,Assumptions!$E$13,IF(G$3<Assumptions!$E$6,Assumptions!$E$14,IF(G$3=Assumptions!$E$6,Assumptions!$E$15,Assumptions!$E$16*(1+Assumptions!$E$17)^(G$3-Assumptions!$E$6-1)))) -> 20000 | H12: =IF(H$3<Assumptions!$E$7,Assumptions!$E$13,IF(H$3<Assumptions!$E$6,Assumptions!$E$14,IF(H$3=Assumptions!$E$6,Assumptions!$E$15,Assumptions!$E$16*(1+Assumptions!$E$17)^(H$3-Assumptions!$E$6-1)))) -> 60000 | I12: =IF(I$3<Assumptions!$E$7,Assumptions!$E$13,IF(I$3<Assumptions!$E$6,Assumptions!$E$14,IF(I$3=Assumptions!$E$6,Assumptions!$E$15,Assumptions!$E$16*(1+Assumptions!$E$17)^(I$3-Assumptions!$E$6-1)))) -> 60000 | J12: =IF(J$3<Assumptions!$E$7,Assumptions!$E$13,IF(J$3<Assumptions!$E$6,Assumptions!$E$14,IF(J$3=Assumptions!$E$6,Assumptions!$E$15,Assumptions!$E$16*(1+Assumptions!$E$17)^(J$3-Assumptions!$E$6-1)))) -> 60000 | K12: =IF(K$3<Assumptions!$E$7,Assumptions!$E$13,IF(K$3<Assumptions!$E$6,Assumptions!$E$14,IF(K$3=Assumptions!$E$6,Assumptions!$E$15,Assumptions!$E$16*(1+Assumptions!$E$17)^(K$3-Assumptions!$E$6-1)))) -> 350000 | ... AM12: =IF(AM$3<Assumptions!$E$7,Assumptions!$E$13,IF(AM$3<Assumptions!$E$6,Assumptions!$E$14,IF(AM$3=Assumptions!$E$6,Assumptions!$E$15,Assumptions!$E$16*(1+Assumptions!$E$17)^(AM$3-Assumptions!$E$6-1)))) -> 399832.02
A13: Paid sessions | B13: sessions | C13: =SUM(D13:AM13) -> 4168783 | D13: =D12/Assumptions!$E$12 -> 10000 | E13: =E12/Assumptions!$E$12 -> 10000 | F13: =F12/Assumptions!$E$12 -> 10000 | G13: =G12/Assumptions!$E$12 -> 10000 | H13: =H12/Assumptions!$E$12 -> 30000 | I13: =I12/Assumptions!$E$12 -> 30000 | J13: =J12/Assumptions!$E$12 -> 30000 | K13: =K12/Assumptions!$E$12 -> 175000 | ... AM13: =AM12/Assumptions!$E$12 -> 199916.01
A14: Organic + direct sessions | B14: sessions | C14: =SUM(D14:AM14) -> 732139.49 | D14: =MIN(Assumptions!$E$11,Assumptions!$E$9*(1+Assumptions!$E$10)^(D$3-1))*IF(AND(D9=1,Assumptions!$E$74=1),Assumptions!$E$78,1) -> 2500 | E14: =MIN(Assumptions!$E$11,Assumptions!$E$9*(1+Assumptions!$E$10)^(E$3-1))*IF(AND(E9=1,Assumptions!$E$74=1),Assumptions!$E$78,1) -> 2725 | F14: =MIN(Assumptions!$E$11,Assumptions!$E$9*(1+Assumptions!$E$10)^(F$3-1))*IF(AND(F9=1,Assumptions!$E$74=1),Assumptions!$E$78,1) -> 2970.25 | G14: =MIN(Assumptions!$E$11,Assumptions!$E$9*(1+Assumptions!$E$10)^(G$3-1))*IF(AND(G9=1,Assumptions!$E$74=1),Assumptions!$E$78,1) -> 3237.5725 | H14: =MIN(Assumptions!$E$11,Assumptions!$E$9*(1+Assumptions!$E$10)^(H$3-1))*IF(AND(H9=1,Assumptions!$E$74=1),Assumptions!$E$78,1) -> 3528.954 | I14: =MIN(Assumptions!$E$11,Assumptions!$E$9*(1+Assumptions!$E$10)^(I$3-1))*IF(AND(I9=1,Assumptions!$E$74=1),Assumptions!$E$78,1) -> 3846.5599 | J14: =MIN(Assumptions!$E$11,Assumptions!$E$9*(1+Assumptions!$E$10)^(J$3-1))*IF(AND(J9=1,Assumptions!$E$74=1),Assumptions!$E$78,1) -> 4192.7503 | K14: =MIN(Assumptions!$E$11,Assumptions!$E$9*(1+Assumptions!$E$10)^(K$3-1))*IF(AND(K9=1,Assumptions!$E$74=1),Assumptions!$E$78,1) -> 5712.6223 | ... AM14: =MIN(Assumptions!$E$11,Assumptions!$E$9*(1+Assumptions!$E$10)^(AM$3-1))*IF(AND(AM9=1,Assumptions!$E$74=1),Assumptions!$E$78,1) -> 63793.65
A15: Total sessions | B15: sessions | C15: =SUM(D15:AM15) -> 4900922.5 | D15: =D13+D14 -> 12500 | E15: =E13+E14 -> 12725 | F15: =F13+F14 -> 12970.25 | G15: =G13+G14 -> 13237.573 | H15: =H13+H14 -> 33528.954 | I15: =I13+I14 -> 33846.56 | J15: =J13+J14 -> 34192.75 | K15: =K13+K14 -> 180712.62 | ... AM15: =AM13+AM14 -> 263709.66
A16: Prescription-program funnel (clinical decisions are independent; rates are monitored, not targeted)
A17: Eligibility quiz starts | B17: # | C17: =SUM(D17:AM17) -> 484948.97 | D17: =D15*Assumptions!$E$19*IF(D$3<Assumptions!$E$7,0,1) -> 0 | E17: =E15*Assumptions!$E$19*IF(E$3<Assumptions!$E$7,0,1) -> 0 | F17: =F15*Assumptions!$E$19*IF(F$3<Assumptions!$E$7,0,1) -> 0 | G17: =G15*Assumptions!$E$19*IF(G$3<Assumptions!$E$7,0,1) -> 0 | H17: =H15*Assumptions!$E$19*IF(H$3<Assumptions!$E$7,0,1) -> 3352.8954 | I17: =I15*Assumptions!$E$19*IF(I$3<Assumptions!$E$7,0,1) -> 3384.656 | J17: =J15*Assumptions!$E$19*IF(J$3<Assumptions!$E$7,0,1) -> 3419.275 | K17: =K15*Assumptions!$E$19*IF(K$3<Assumptions!$E$7,0,1) -> 18071.262 | ... AM17: =AM15*Assumptions!$E$19*IF(AM$3<Assumptions!$E$7,0,1) -> 26370.966
A18: Quiz completions | B18: # | C18: =SUM(D18:AM18) -> 339464.28 | D18: =D17*Assumptions!$E$20 -> 0 | E18: =E17*Assumptions!$E$20 -> 0 | F18: =F17*Assumptions!$E$20 -> 0 | G18: =G17*Assumptions!$E$20 -> 0 | H18: =H17*Assumptions!$E$20 -> 2347.0268 | I18: =I17*Assumptions!$E$20 -> 2369.2592 | J18: =J17*Assumptions!$E$20 -> 2393.4925 | K18: =K17*Assumptions!$E$20 -> 12649.884 | ... AM18: =AM17*Assumptions!$E$20 -> 18459.676
A19: Eligible outcomes (screen + state) | B19: # | C19: =SUM(D19:AM19) -> 152082.7 | D19: =D18*Assumptions!$E$21*D10 -> 0 | E19: =E18*Assumptions!$E$21*E10 -> 0 | F19: =F18*Assumptions!$E$21*F10 -> 0 | G19: =G18*Assumptions!$E$21*G10 -> 0 | H19: =H18*Assumptions!$E$21*H10 -> 281.64321 | I19: =I18*Assumptions!$E$21*I10 -> 284.3111 | J19: =J18*Assumptions!$E$21*J10 -> 287.2191 | K19: =K18*Assumptions!$E$21*K10 -> 3035.9721 | ... AM19: =AM18*Assumptions!$E$21*AM10 -> 9414.4349
A20: Intakes submitted (consult fee charged) | B20: # | C20: =SUM(D20:AM20) -> 83645.484 | D20: =D19*Assumptions!$E$25 -> 0 | E20: =E19*Assumptions!$E$25 -> 0 | F20: =F19*Assumptions!$E$25 -> 0 | G20: =G19*Assumptions!$E$25 -> 0 | H20: =H19*Assumptions!$E$25 -> 154.90377 | I20: =I19*Assumptions!$E$25 -> 156.37111 | J20: =J19*Assumptions!$E$25 -> 157.97051 | K20: =K19*Assumptions!$E$25 -> 1669.7846 | ... AM20: =AM19*Assumptions!$E$25 -> 5177.9392
A21: Consults completed | B21: # | C21: =SUM(D21:AM21) -> 68589.297 | D21: =D20*Assumptions!$E$26 -> 0 | E21: =E20*Assumptions!$E$26 -> 0 | F21: =F20*Assumptions!$E$26 -> 0 | G21: =G20*Assumptions!$E$26 -> 0 | H21: =H20*Assumptions!$E$26 -> 127.02109 | I21: =I20*Assumptions!$E$26 -> 128.22431 | J21: =J20*Assumptions!$E$26 -> 129.53582 | K21: =K20*Assumptions!$E$26 -> 1369.2234 | ... AM21: =AM20*Assumptions!$E$26 -> 4245.9101
A22: Prescriptions issued (clinician decision) | B22: # | C22: =SUM(D22:AM22) -> 42525.364 | D22: =D21*Assumptions!$E$27 -> 0 | E22: =E21*Assumptions!$E$27 -> 0 | F22: =F21*Assumptions!$E$27 -> 0 | G22: =G21*Assumptions!$E$27 -> 0 | H22: =H21*Assumptions!$E$27 -> 78.753075 | I22: =I21*Assumptions!$E$27 -> 79.499071 | J22: =J21*Assumptions!$E$27 -> 80.312205 | K22: =K21*Assumptions!$E$27 -> 848.91851 | ... AM22: =AM21*Assumptions!$E$27 -> 2632.4643
A23: New paying Rx program members | B23: # | C23: =SUM(D23:AM23) -> 27641.487 | D23: =D22*Assumptions!$E$28 -> 0 | E23: =E22*Assumptions!$E$28 -> 0 | F23: =F22*Assumptions!$E$28 -> 0 | G23: =G22*Assumptions!$E$28 -> 0 | H23: =H22*Assumptions!$E$28 -> 51.189499 | I23: =I22*Assumptions!$E$28 -> 51.674396 | J23: =J22*Assumptions!$E$28 -> 52.202934 | K23: =K22*Assumptions!$E$28 -> 551.79703 | ... AM23: =AM22*Assumptions!$E$28 -> 1711.1018
A24: Active Rx program members (end of month) | B24: # | D24: =D23 -> 0 | E24: =D24*(1-Assumptions!$E$41)+E23 -> 0 | F24: =E24*(1-Assumptions!$E$41)+F23 -> 0 | G24: =F24*(1-Assumptions!$E$41)+G23 -> 0 | H24: =G24*(1-Assumptions!$E$41)+H23 -> 51.189499 | I24: =H24*(1-Assumptions!$E$41)+I23 -> 97.23305 | J24: =I24*(1-Assumptions!$E$41)+J23 -> 138.74035 | K24: =J24*(1-Assumptions!$E$41)+K23 -> 675.27594 | L24: =K24*(1-Assumptions!$E$41)+L23 -> 916.85599 | ... AM24: =AL24*(1-Assumptions!$E$41)+AM23 -> 11437.582
A25: Rx members churned | B25: # | C25: =SUM(D25:AM25) -> 16203.905 | D25: =0 -> 0 | E25: =D24*Assumptions!$E$41 -> 0 | F25: =E24*Assumptions!$E$41 -> 0 | G25: =F24*Assumptions!$E$41 -> 0 | H25: =G24*Assumptions!$E$41 -> 0 | I25: =H24*Assumptions!$E$41 -> 5.6308449 | J25: =I24*Assumptions!$E$41 -> 10.695636 | K25: =J24*Assumptions!$E$41 -> 15.261438 | L25: =K24*Assumptions!$E$41 -> 74.280353 | ... AM25: =AL24*Assumptions!$E$41 -> 1202.1492
A26: Lab panels ordered | B26: # | C26: =SUM(D26:AM26) -> 41822.742 | D26: =D20*Assumptions!$E$32 -> 0 | E26: =E20*Assumptions!$E$32 -> 0 | F26: =F20*Assumptions!$E$32 -> 0 | G26: =G20*Assumptions!$E$32 -> 0 | H26: =H20*Assumptions!$E$32 -> 77.451884 | I26: =I20*Assumptions!$E$32 -> 78.185553 | J26: =J20*Assumptions!$E$32 -> 78.985253 | K26: =K20*Assumptions!$E$32 -> 834.89231 | ... AM26: =AM20*Assumptions!$E$32 -> 2588.9696
A27: Membership and non-prescription commerce
A28: New membership sign-ups | B28: # | C28: =SUM(D28:AM28) -> 16092.385 | D28: =(D18-D19)*Assumptions!$E$35+D15*Assumptions!$E$36*IF(D$3<Assumptions!$E$7,0,1) -> 0 | E28: =(E18-E19)*Assumptions!$E$35+E15*Assumptions!$E$36*IF(E$3<Assumptions!$E$7,0,1) -> 0 | F28: =(F18-F19)*Assumptions!$E$35+F15*Assumptions!$E$36*IF(F$3<Assumptions!$E$7,0,1) -> 0 | G28: =(G18-G19)*Assumptions!$E$35+G15*Assumptions!$E$36*IF(G$3<Assumptions!$E$7,0,1) -> 0 | H28: =(H18-H19)*Assumptions!$E$35+H15*Assumptions!$E$36*IF(H$3<Assumptions!$E$7,0,1) -> 157.45197 | I28: =(I18-I19)*Assumptions!$E$35+I15*Assumptions!$E$36*IF(I$3<Assumptions!$E$7,0,1) -> 158.94345 | J28: =(J18-J19)*Assumptions!$E$35+J15*Assumptions!$E$36*IF(J$3<Assumptions!$E$7,0,1) -> 160.56916 | K28: =(K18-K19)*Assumptions!$E$35+K15*Assumptions!$E$36*IF(K$3<Assumptions!$E$7,0,1) -> 757.54731 | ... AM28: =(AM18-AM19)*Assumptions!$E$35+AM15*Assumptions!$E$36*IF(AM$3<Assumptions!$E$7,0,1) -> 806.42414
A29: Active members (end of month) | B29: # | D29: =D28 -> 0 | E29: =D29*(1-Assumptions!$E$42)+E28 -> 0 | F29: =E29*(1-Assumptions!$E$42)+F28 -> 0 | G29: =F29*(1-Assumptions!$E$42)+G28 -> 0 | H29: =G29*(1-Assumptions!$E$42)+H28 -> 157.45197 | I29: =H29*(1-Assumptions!$E$42)+I28 -> 306.9483 | J29: =I29*(1-Assumptions!$E$42)+J28 -> 449.10055 | K29: =J29*(1-Assumptions!$E$42)+K28 -> 1179.7018 | L29: =K29*(1-Assumptions!$E$42)+L28 -> 1505.0275 | ... AM29: =AL29*(1-Assumptions!$E$42)+AM28 -> 8289.8763
A30: Members churned | B30: # | C30: =SUM(D30:AM30) -> 7802.5082 | D30: =0 -> 0 | E30: =D29*Assumptions!$E$42 -> 0 | F30: =E29*Assumptions!$E$42 -> 0 | G30: =F29*Assumptions!$E$42 -> 0 | H30: =G29*Assumptions!$E$42 -> 0 | I30: =H29*Assumptions!$E$42 -> 9.4471181 | J30: =I29*Assumptions!$E$42 -> 18.416898 | K30: =J29*Assumptions!$E$42 -> 26.946033 | L30: =K29*Assumptions!$E$42 -> 70.78211 | ... AM30: =AL29*Assumptions!$E$42 -> 477.66716
A31: Non-Rx first orders | B31: # | C31: =SUM(D31:AM31) -> 43645.407 | D31: =D15*Assumptions!$E$37*IF(D$3<Assumptions!$E$7,0,1) -> 0 | E31: =E15*Assumptions!$E$37*IF(E$3<Assumptions!$E$7,0,1) -> 0 | F31: =F15*Assumptions!$E$37*IF(F$3<Assumptions!$E$7,0,1) -> 0 | G31: =G15*Assumptions!$E$37*IF(G$3<Assumptions!$E$7,0,1) -> 0 | H31: =H15*Assumptions!$E$37*IF(H$3<Assumptions!$E$7,0,1) -> 301.76059 | I31: =I15*Assumptions!$E$37*IF(I$3<Assumptions!$E$7,0,1) -> 304.61904 | J31: =J15*Assumptions!$E$37*IF(J$3<Assumptions!$E$7,0,1) -> 307.73475 | K31: =K15*Assumptions!$E$37*IF(K$3<Assumptions!$E$7,0,1) -> 1626.4136 | ... AM31: =AM15*Assumptions!$E$37*IF(AM$3<Assumptions!$E$7,0,1) -> 2373.3869
A32: Cumulative non-Rx customers | B32: # | D32: =D31 -> 0 | E32: =D32+E31 -> 0 | F32: =E32+F31 -> 0 | G32: =F32+G31 -> 0 | H32: =G32+H31 -> 301.76059 | I32: =H32+I31 -> 606.37963 | J32: =I32+J31 -> 914.11438 | K32: =J32+K31 -> 2540.528 | L32: =K32+L31 -> 3406.5688 | ... AM32: =AL32+AM31 -> 43645.407
A33: Non-Rx repeat orders | B33: # | C33: =SUM(D33:AM33) -> 79349.94 | D33: =0 -> 0 | E33: =D32*Assumptions!$E$39 -> 0 | F33: =E32*Assumptions!$E$39 -> 0 | G33: =F32*Assumptions!$E$39 -> 0 | H33: =G32*Assumptions!$E$39 -> 0 | I33: =H32*Assumptions!$E$39 -> 45.264088 | J33: =I32*Assumptions!$E$39 -> 90.956944 | K33: =J32*Assumptions!$E$39 -> 137.11716 | L33: =K32*Assumptions!$E$39 -> 381.0792 | ... AM33: =AL32*Assumptions!$E$39 -> 6190.803
A34: Total non-Rx orders | B34: # | C34: =SUM(D34:AM34) -> 122995.35 | D34: =D31+D33 -> 0 | E34: =E31+E33 -> 0 | F34: =F31+F33 -> 0 | G34: =G31+G33 -> 0 | H34: =H31+H33 -> 301.76059 | I34: =I31+I33 -> 349.88313 | J34: =J31+J33 -> 398.6917 | K34: =K31+K33 -> 1763.5308 | ... AM34: =AM31+AM33 -> 8564.19
A35: Revenue
A36: Rx program revenue (all-in monthly) | B36: $ | C36: =SUM(D36:AM36) -> 43655096 | D36: =D24*Assumptions!$E$30 -> 0 | E36: =E24*Assumptions!$E$30 -> 0 | F36: =F24*Assumptions!$E$30 -> 0 | G36: =G24*Assumptions!$E$30 -> 0 | H36: =H24*Assumptions!$E$30 -> 14077.112 | I36: =I24*Assumptions!$E$30 -> 26739.089 | J36: =J24*Assumptions!$E$30 -> 38153.596 | K36: =K24*Assumptions!$E$30 -> 185700.88 | ... AM36: =AM24*Assumptions!$E$30 -> 3145335.1
A37: Consultation revenue | B37: $ | C37: =SUM(D37:AM37) -> 6607993.2 | D37: =D20*Assumptions!$E$31 -> 0 | E37: =E20*Assumptions!$E$31 -> 0 | F37: =F20*Assumptions!$E$31 -> 0 | G37: =G20*Assumptions!$E$31 -> 0 | H37: =H20*Assumptions!$E$31 -> 12237.398 | I37: =I20*Assumptions!$E$31 -> 12353.317 | J37: =J20*Assumptions!$E$31 -> 12479.67 | K37: =K20*Assumptions!$E$31 -> 131912.99 | ... AM37: =AM20*Assumptions!$E$31 -> 409057.2
A38: Lab revenue | B38: $ | C38: =SUM(D38:AM38) -> 4976906.3 | D38: =D26*Assumptions!$E$33 -> 0 | E38: =E26*Assumptions!$E$33 -> 0 | F38: =F26*Assumptions!$E$33 -> 0 | G38: =G26*Assumptions!$E$33 -> 0 | H38: =H26*Assumptions!$E$33 -> 9216.7742 | I38: =I26*Assumptions!$E$33 -> 9304.0808 | J38: =J26*Assumptions!$E$33 -> 9399.2451 | K38: =K26*Assumptions!$E$33 -> 99352.185 | ... AM38: =AM26*Assumptions!$E$33 -> 308087.38
A39: Membership revenue | B39: $ | C39: =SUM(D39:AM39) -> 4011618.7 | D39: =D29*Assumptions!$E$34 -> 0 | E39: =E29*Assumptions!$E$34 -> 0 | F39: =F29*Assumptions!$E$34 -> 0 | G39: =G29*Assumptions!$E$34 -> 0 | H39: =H29*Assumptions!$E$34 -> 4566.1071 | I39: =I29*Assumptions!$E$34 -> 8901.5006 | J39: =J29*Assumptions!$E$34 -> 13023.916 | K39: =K29*Assumptions!$E$34 -> 34211.353 | ... AM39: =AM29*Assumptions!$E$34 -> 240406.41
A40: Non-Rx commerce revenue | B40: $ | C40: =SUM(D40:AM40) -> 9224651.1 | D40: =D34*Assumptions!$E$38 -> 0 | E40: =E34*Assumptions!$E$38 -> 0 | F40: =F34*Assumptions!$E$38 -> 0 | G40: =G34*Assumptions!$E$38 -> 0 | H40: =H34*Assumptions!$E$38 -> 22632.044 | I40: =I34*Assumptions!$E$38 -> 26241.235 | J40: =J34*Assumptions!$E$38 -> 29901.877 | K40: =K34*Assumptions!$E$38 -> 132264.81 | ... AM40: =AM34*Assumptions!$E$38 -> 642314.25
...

Sheet Model_Upside
A1: Reserve Clinic monthly model — Upside scenario (all cells are formulas driven by the Assumptions sheet)
A2: Units: $ unless noted. Month 1 = start of Phase 0. Prescription programs run through an affiliated medical practice and licensed pharmacies; revenue recognition and merchant-of-record structure subject to counsel.
A3: Line | B3: Unit | C3: 36-mo total | D3: 1 | E3: 2 | F3: 3 | G3: 4 | H3: 5 | I3: 6 | J3: 7 | K3: 8 | L3: 9 | M3: 10 | N3: 11 | O3: 12 | P3: 13 | Q3: 14 | R3: 15 | S3: 16 | T3: 17 | U3: 18 | V3: 19 | W3: 20 | X3: 21 | Y3: 22 | Z3: 23 | AA3: 24 | AB3: 25 | AC3: 26 | AD3: 27 | AE3: 28 | AF3: 29 | AG3: 30 | AH3: 31 | AI3: 32 | AJ3: 33 | AK3: 34 | AL3: 35 | AM3: 36
A4: Timing & coverage
A5: Model month | B5: # | D5: =D$3 -> 1 | E5: =E$3 -> 2 | F5: =F$3 -> 3 | G5: =G$3 -> 4 | H5: =H$3 -> 5 | I5: =I$3 -> 6 | J5: =J$3 -> 7 | K5: =K$3 -> 8 | ... AM5: =AM$3 -> 36
A6: Pre-beta phase flag | B6: flag | D6: =IF(D$3<Assumptions!$F$7,1,0) -> 1 | E6: =IF(E$3<Assumptions!$F$7,1,0) -> 1 | F6: =IF(F$3<Assumptions!$F$7,1,0) -> 1 | G6: =IF(G$3<Assumptions!$F$7,1,0) -> 1 | H6: =IF(H$3<Assumptions!$F$7,1,0) -> 0 | I6: =IF(I$3<Assumptions!$F$7,1,0) -> 0 | J6: =IF(J$3<Assumptions!$F$7,1,0) -> 0 | K6: =IF(K$3<Assumptions!$F$7,1,0) -> 0 | ... AM6: =IF(AM$3<Assumptions!$F$7,1,0) -> 0
A7: Beta/waitlist phase flag | B7: flag | D7: =IF(AND(D$3>=Assumptions!$F$7,D$3<Assumptions!$F$6),1,0) -> 0 | E7: =IF(AND(E$3>=Assumptions!$F$7,E$3<Assumptions!$F$6),1,0) -> 0 | F7: =IF(AND(F$3>=Assumptions!$F$7,F$3<Assumptions!$F$6),1,0) -> 0 | G7: =IF(AND(G$3>=Assumptions!$F$7,G$3<Assumptions!$F$6),1,0) -> 0 | H7: =IF(AND(H$3>=Assumptions!$F$7,H$3<Assumptions!$F$6),1,0) -> 1 | I7: =IF(AND(I$3>=Assumptions!$F$7,I$3<Assumptions!$F$6),1,0) -> 1 | J7: =IF(AND(J$3>=Assumptions!$F$7,J$3<Assumptions!$F$6),1,0) -> 0 | K7: =IF(AND(K$3>=Assumptions!$F$7,K$3<Assumptions!$F$6),1,0) -> 0 | ... AM7: =IF(AND(AM$3>=Assumptions!$F$7,AM$3<Assumptions!$F$6),1,0) -> 0
A8: Launch month flag | B8: flag | D8: =IF(D$3=Assumptions!$F$6,1,0) -> 0 | E8: =IF(E$3=Assumptions!$F$6,1,0) -> 0 | F8: =IF(F$3=Assumptions!$F$6,1,0) -> 0 | G8: =IF(G$3=Assumptions!$F$6,1,0) -> 0 | H8: =IF(H$3=Assumptions!$F$6,1,0) -> 0 | I8: =IF(I$3=Assumptions!$F$6,1,0) -> 0 | J8: =IF(J$3=Assumptions!$F$6,1,0) -> 1 | K8: =IF(K$3=Assumptions!$F$6,1,0) -> 0 | ... AM8: =IF(AM$3=Assumptions!$F$6,1,0) -> 0
A9: Post-launch flag (incl. launch month) | B9: flag | D9: =IF(D$3>=Assumptions!$F$6,1,0) -> 0 | E9: =IF(E$3>=Assumptions!$F$6,1,0) -> 0 | F9: =IF(F$3>=Assumptions!$F$6,1,0) -> 0 | G9: =IF(G$3>=Assumptions!$F$6,1,0) -> 0 | H9: =IF(H$3>=Assumptions!$F$6,1,0) -> 0 | I9: =IF(I$3>=Assumptions!$F$6,1,0) -> 0 | J9: =IF(J$3>=Assumptions!$F$6,1,0) -> 1 | K9: =IF(K$3>=Assumptions!$F$6,1,0) -> 1 | ... AM9: =IF(AM$3>=Assumptions!$F$6,1,0) -> 1
A10: Population coverage of served states (Rx) | B10: % | D10: =IF(D$3<Assumptions!$F$7,0,IF(D$3<Assumptions!$F$6,Assumptions!$F$22*0.5,MIN(Assumptions!$F$24,Assumptions!$F$22+Assumptions!$F$23*(D$3-Assumptions!$F$6)))) -> 0 | E10: =IF(E$3<Assumptions!$F$7,0,IF(E$3<Assumptions!$F$6,Assumptions!$F$22*0.5,MIN(Assumptions!$F$24,Assumptions!$F$22+Assumptions!$F$23*(E$3-Assumptions!$F$6)))) -> 0 | F10: =IF(F$3<Assumptions!$F$7,0,IF(F$3<Assumptions!$F$6,Assumptions!$F$22*0.5,MIN(Assumptions!$F$24,Assumptions!$F$22+Assumptions!$F$23*(F$3-Assumptions!$F$6)))) -> 0 | G10: =IF(G$3<Assumptions!$F$7,0,IF(G$3<Assumptions!$F$6,Assumptions!$F$22*0.5,MIN(Assumptions!$F$24,Assumptions!$F$22+Assumptions!$F$23*(G$3-Assumptions!$F$6)))) -> 0 | H10: =IF(H$3<Assumptions!$F$7,0,IF(H$3<Assumptions!$F$6,Assumptions!$F$22*0.5,MIN(Assumptions!$F$24,Assumptions!$F$22+Assumptions!$F$23*(H$3-Assumptions!$F$6)))) -> 0.225 | I10: =IF(I$3<Assumptions!$F$7,0,IF(I$3<Assumptions!$F$6,Assumptions!$F$22*0.5,MIN(Assumptions!$F$24,Assumptions!$F$22+Assumptions!$F$23*(I$3-Assumptions!$F$6)))) -> 0.225 | J10: =IF(J$3<Assumptions!$F$7,0,IF(J$3<Assumptions!$F$6,Assumptions!$F$22*0.5,MIN(Assumptions!$F$24,Assumptions!$F$22+Assumptions!$F$23*(J$3-Assumptions!$F$6)))) -> 0.45 | K10: =IF(K$3<Assumptions!$F$7,0,IF(K$3<Assumptions!$F$6,Assumptions!$F$22*0.5,MIN(Assumptions!$F$24,Assumptions!$F$22+Assumptions!$F$23*(K$3-Assumptions!$F$6)))) -> 0.485 | ... AM10: =IF(AM$3<Assumptions!$F$7,0,IF(AM$3<Assumptions!$F$6,Assumptions!$F$22*0.5,MIN(Assumptions!$F$24,Assumptions!$F$22+Assumptions!$F$23*(AM$3-Assumptions!$F$6)))) -> 0.9
A11: Traffic
