Workbook

Sheet Read_Me
A1: Reserve Clinic - Margin and Growth Model
A3: What this is
A4: A driver-based 36-month model of a two-line peptide and supplement business: a non-prescription supplement line that can trade in all fifty states, and a prescription telehealth line fulfilled by 503A and 503B pharmacies whose state footprint expands over time. It is built for the specific operating structure the project owner described, including a turnkey compliance-and-fulfilment provider at a flat $600 per month. Three scenarios: Conservative, Baseline, Aggressive.
A6: What it is not
A7: Not a forecast, not a valuation, and not legal, medical, tax or investment advice. The outputs follow arithmetically from the drivers on the Assumptions sheet. Change a driver and the answer changes. Several of the most consequential drivers rest on analyst assumptions rather than measurements, and those are labelled Low confidence with a stated validation method.
A9: Status of the people named
A10: The proposed brand partner and the proposed medical co-founder are treated strictly as proposed. No public evidence connects either to this venture, no agreement exists, and nothing in this workbook is an offer or implies endorsement, ownership or authorisation. Partner compensation figures are illustrative arithmetic, not terms.
A12: Colour key
A13: Blue = editable input, on the Assumptions sheet only. Black = formula. Green = link to another sheet. Yellow fill = high-sensitivity driver: get these wrong and the answer changes materially. Peach fill = a caution the reader should not skip.
A15: Sheet order
A16: Summary reads the three scenarios side by side. Unit_Economics shows where margin comes from per order and per member-month. Sensitivity shows which assumptions decide the outcome. Partner_Economics is illustrative deal arithmetic. Provider_Diligence is the twenty questions to answer in writing before signing. Benchmarks is the evidence. Assumptions holds every input. Model_Conservative, Model_Baseline and Model_Aggressive are the monthly grids.
A18: The three things most likely to be wrong
... A25: 2026-09-18. Rebuild with: python3 build/build_margin_model.py outputs/09_ReserveClinic_Margin_and_Growth_Model.xlsx

Sheet Assumptions
A1: Reserve Clinic - Margin and Growth Model: Assumptions
A2: Blue cells are the only inputs. Three scenario columns drive Model_Conservative, Model_Baseline and Model_Aggressive. Yellow fill marks high-sensitivity drivers. Prepared 2026-09-18. Proposed concept: the brand partner's and the medical co-founder's participation is unverified and subject to definitive agreements. Not legal, medical, tax or investment advice.
A4: Key | B4: Driver | C4: Unit | D4: Conservative | E4: Baseline | F4: Aggressive | G4: Rationale / source | H4: Confidence | I4: Sensitivity | J4: Validation method
A5: Timing and sequencing
A6: nonrx_launch | B6: Non-prescription line goes live (model month) | C6: month | D6: 3 | E6: 2 | F6: 2 | G6: Supplement line needs only manufacturing, label/claims review and a storefront. Conservative allows one month of slippage on label review. | H6: High | I6: Medium | J6: Phase exit checklist
A7: rx_launch | B7: Prescription telehealth line goes live (model month) | C7: month | D7: 9 | E7: 7 | F7: 5 | G7: Requires the provider agreement, physician entity, pharmacy contracts, LegitScript certification and a state-by-state licensure map. Benchmark B10, B11. | H7: Medium | I7: High | J7: Counsel and provider go-live sign-off
A8: Audience engine (the proposed brand partner's reach)
A9: followers | B9: Proposed brand partner Instagram followers | C9: # | D9: 27400000 | E9: 27400000 | F9: 27400000 | G9: Third-party trackers report 27,410,219 as of June 2026 (range 27.0M-28.3M). Benchmark B16. Held constant across scenarios because it is measured, not chosen. NOT an audited or first-party figure. | H9: Medium | I9: High | J9: First-party creator analytics export
A10: posts_per_month | B10: Brand posts per month by the partner (feed plus reels) | C10: # | D10: 2 | E10: 4 | F10: 6 | G10: A contract deliverable, not a market variable. Set to whatever the agreement actually obliges. | H10: n/a | I10: High | J10: Signed content schedule
A11: reach_pct | B11: Reach per brand post as a share of followers | C11: % | D11: 0.04 | E11: 0.07 | F11: 0.11 | G11: Analyst assumption bounded by benchmark B15: the 10M-plus tier averages ~1.77% ENGAGEMENT; reach exceeds engagement but organic reach at this tier is heavily throttled and branded content more so. Reels reach higher than static. | H11: Low | I11: High | J11: Creator-account reach data, first 60 days
A12: ctr_reach | B12: Click-through to site per reached impression | C12: % | D12: 0.0035 | E12: 0.006 | F12: 0.009 | G12: Analyst assumption. No tier-level link-click benchmark was retrievable (benchmark B15 notes this gap). This is the single least-evidenced driver in the model. | H12: Low | I12: High | J12: UTM-tagged link data, first 30 days
A13: attn_decay | B13: Monthly decay of partner-driven traffic toward a floor | C13: % | D13: 0.72 | E13: 0.8 | F13: 0.86 | G13: Analyst assumption. Celebrity launch demand spikes then settles; benchmark B14 notes IM8's founders deliberately did not rely on fame for durability. | H13: Low | I13: High | J13: Cohort traffic by source, monthly
A14: attn_floor | B14: Floor for partner-driven traffic as a share of the launch peak | C14: % | D14: 0.28 | E14: 0.36 | F14: 0.45 | G14: Analyst assumption. Represents the durable follower demand that persists after novelty. | H14: Low | I14: High | J14: Cohort traffic by source, monthly
A15: launch_spike | B15: Launch-month multiplier on partner-driven traffic | C15: x | D15: 1.6 | E15: 2.2 | F15: 3 | G15: Announcement window concentrates attention. Analyst assumption. | H15: Low | I15: Medium | J15: Launch-week analytics
A16: Other traffic
A17: organic_m1 | B17: Organic and direct sessions, month 1 | C17: sessions | D17: 1200 | E17: 2200 | F17: 3500 | G17: New domain with an editorial library. Analyst assumption. | H17: Low | I17: Low | J17: GA4 after month 1
A18: organic_growth | B18: Organic monthly growth rate | C18: % | D18: 0.06 | E18: 0.09 | F18: 0.12 | G18: Content-led SEO compounding from a small base. Analyst inference. | H18: Low | I18: Medium | J18: Search Console trend
A19: organic_cap | B19: Organic and direct sessions ceiling | C19: sessions | D19: 90000 | E19: 180000 | F19: 320000 | G19: Caps compounding; category search demand is finite. Analyst inference. | H19: Low | I19: Medium | J19: Search Console
A20: cps | B20: Cost per paid session, blended | C20: $ | D20: 2.6 | E20: 2.15 | F20: 1.85 | G20: Health and wellness CPC proxies; restricted-category ad review raises cost. LegitScript certification is a precondition for scaled healthcare advertising (benchmark B10). | H20: Medium | I20: High | J20: Ad platform reports
A21: paid_pre | B21: Paid media per month before the non-Rx launch | C21: $ | D21: 4000 | E21: 8000 | F21: 15000 | G21: Waitlist and audience building only. | H21: Medium | I21: Low | J21: Budget actuals
A22: paid_floor | B22: Minimum paid media per month after launch | C22: $ | D22: 10000 | E22: 30000 | F22: 60000 | G22: Keeps a spend floor while revenue is small. | H22: Medium | I22: Medium | J22: Budget actuals
A23: paid_pct | B23: Paid media as a share of prior-month net revenue | C23: % | D23: 0.3 | E23: 0.24 | F23: 0.2 | G23: Benchmark B02: the closest listed telehealth comparable ran marketing at 35-40% of revenue. A celebrity-led brand should sit WELL below that, because the point of the partnership is that owned audience substitutes for bought audience; if this driver has to rise toward 35% the partnership is not working. Prior-month basis avoids a circular reference. | H23: Medium | I23: High | J23: Monthly payback review
A24: launch_push | B24: One-time launch marketing and PR, non-Rx launch month | C24: $ | D24: 40000 | E24: 150000 | F24: 400000 | G24: Announcement window spend: PR, production, seeding, paid amplification. Concentrated in a single month by design. | H24: Medium | I24: Medium | J24: Agency scopes
A25: paid_cap | B25: Maximum paid media per month | C25: $ | D25: 200000 | E25: 900000 | F25: 2500000 | G25: A budget ceiling and a reality check. Without one, a percent-of-revenue rule compounds without limit. At the Aggressive ceiling this is roughly 25-30% of revenue at scale, in line with benchmark B02. | H25: Medium | I25: High | J25: Board-approved budget
A26: paid_elast | B26: Paid response elasticity (sessions per marginal dollar) | C26: x | D26: 0.68 | E26: 0.75 | F26: 0.82 | G26: Diminishing returns. Sessions scale as (spend / floor) raised to this power, so at ten times the floor spend the effective cost per session rises about 1.8x at 0.75. Below 1.0 is the whole point: auction competition and audience exhaustion mean the second million never buys what the first did. Analyst assumption, standard media-mix practice. | H26: Low | I26: High | J26: Marginal CAC by spend decile
A27: Non-prescription line: funnel and pricing
A28: cap_m1 | B28: Orders the supply chain can ship in the first live month | C28: # | D28: 600 | E28: 1500 | F28: 3000 | G28: Manufacturing minimum order quantities, batch lead times, label print runs and 3PL onboarding all gate the first months. Demand above this ceiling is treated as LOST, not backlogged, which is the conservative treatment. Analyst assumption; replace with the contract manufacturer's actual run schedule. | H28: Low | I28: High | J28: Manufacturer run schedule and 3PL onboarding plan
A29: cap_growth | B29: Monthly growth in shippable capacity | C29: x | D29: 1.25 | E29: 1.35 | F29: 1.45 | G29: How fast production and fulfilment can be scaled. Binds hard in the first year of the Aggressive case and stops binding thereafter. Analyst assumption. | H29: Low | I29: High | J29: Purchase-order lead times
A30: shop_conv | B30: Order conversion rate, all sessions | C30: % | D30: 0.009 | E30: 0.014 | F30: 0.019 | G30: DTC supplement conversion commonly 0.5-1.5%; a warm follower audience should sit at the top of or above that band, but benchmark B15 warns mega-tier audiences convert worse than their reach implies. | H30: Low | I30: High | J30: Shopify analytics
A31: nonrx_aov | B31: Average order value | C31: $ | D31: 68 | E31: 78 | F31: 88 | G31: Above the $30-65 monthly band in benchmark B06, reflecting a premium multi-product basket. Requires validation. | H31: Medium | I31: High | J31: Shopify analytics
A32: sub_attach | B32: Share of new customers taking a subscription | C32: % | D32: 0.3 | E32: 0.4 | F32: 0.5 | G32: Subscribe-and-save attach on consumables. Analyst assumption. | H32: Low | I32: High | J32: Subscription app data
A33: sub_churn | B33: Monthly subscription churn | C33: % | D33: 0.09 | E33: 0.07 | F33: 0.055 | G33: Benchmark B05: 4-7% monthly well run, 8-12% category average, 12-20% churning in month one alone. | H33: Medium | I33: High | J33: Cohort analysis
A34: onetime_repeat | B34: Monthly reorder rate of one-time buyers | C34: % | D34: 0.08 | E34: 0.11 | F34: 0.14 | G34: Approximation: applied to the prior month's one-time cohort only, which understates a long tail and is deliberately conservative. | H34: Low | I34: Medium | J34: Cohort analysis
A35: Non-prescription line: cost of revenue
A36: nonrx_cogs_pct | B36: Landed product COGS as a share of retail | C36: % | D36: 0.3 | E36: 0.26 | F36: 0.22 | G36: Benchmark B03: landed COGS 20-30% of retail for DTC supplements, giving 70-80% product gross margin. | H36: Medium | I36: High | J36: Contract manufacturer quotes
A37: nonrx_fulfil | B37: Pick, pack and ship per order (ambient) | C37: $ | D37: 8.5 | E37: 7.5 | F37: 6.5 | G37: 3PL pick-pack plus domestic parcel. Ambient, not cold chain. | H37: Medium | I37: Low | J37: 3PL quotes
A38: Prescription line: funnel
A39: rx_intent | B39: Eligibility-quiz start rate, all sessions | C39: % | D39: 0.012 | E39: 0.018 | F39: 0.025 | G39: Analyst assumption. Prescription intent is a small slice of brand traffic. | H39: Low | I39: High | J39: Analytics
A40: quiz_complete | B40: Quiz completion rate | C40: % | D40: 0.6 | E40: 0.7 | F40: 0.76 | G40: One-question-per-screen intake typically 55-75%. | H40: Medium | I40: Medium | J40: Analytics
A41: eligible_rate | B41: Share of completions with a clinically eligible outcome | C41: % | D41: 0.5 | E41: 0.58 | F41: 0.64 | G41: Red-flag screening removes a material share. Never a target; a safety control. | H41: Medium | I41: Medium | J41: Medical director audit
...

Sheet Summary
A1: Reserve Clinic - Margin and Growth Summary
A2: All figures are model outputs, not forecasts. They follow arithmetically from the drivers on Assumptions. Read them as a band produced by a stated set of assumptions, each of which is listed with its confidence and its validation method. Proposed concept; partner participation unverified.
A4: Metric | B4: Conservative | C4: Baseline | D4: Aggressive
A5: Net revenue, year 1 | B5: =SUM(Model_Conservative!C60:N60) -> 128902.31 | C5: =SUM(Model_Baseline!C60:N60) -> 1837396.5 | D5: =SUM(Model_Aggressive!C60:N60) -> 15330885
A6: Net revenue, year 2 | B6: =SUM(Model_Conservative!O60:Z60) -> 243504.43 | C6: =SUM(Model_Baseline!O60:Z60) -> 4069835.8 | D6: =SUM(Model_Aggressive!O60:Z60) -> 62800309
A7: Net revenue, year 3 | B7: =SUM(Model_Conservative!AA60:AL60) -> 352473.95 | C7: =SUM(Model_Baseline!AA60:AL60) -> 7063186.2 | D7: =SUM(Model_Aggressive!AA60:AL60) -> 1.3854843e+08
A8: Net revenue, 36-month total | B8: =SUM(Model_Conservative!C60:AL60) -> 724880.69 | C8: =SUM(Model_Baseline!C60:AL60) -> 12970419 | D8: =SUM(Model_Aggressive!C60:AL60) -> 2.1667962e+08
A10: Gross profit, year 3 | B10: =SUM(Model_Conservative!AA61:AL61) -> 170760.36 | C10: =SUM(Model_Baseline!AA61:AL61) -> 3999705.8 | D10: =SUM(Model_Aggressive!AA61:AL61) -> 90678495
A11: Blended gross margin, year 1 | B11: =IFERROR(SUM(Model_Conservative!C61:N61)/SUM(Model_Conservative!C60:N60),0) -> 0.51959308 | C11: =IFERROR(SUM(Model_Baseline!C61:N61)/SUM(Model_Baseline!C60:N60),0) -> 0.59376752 | D11: =IFERROR(SUM(Model_Aggressive!C61:N61)/SUM(Model_Aggressive!C60:N60),0) -> 0.66098121
A12: Blended gross margin, year 3 | B12: =IFERROR(SUM(Model_Conservative!AA61:AL61)/SUM(Model_Conservative!AA60:AL60),0) -> 0.48446234 | C12: =IFERROR(SUM(Model_Baseline!AA61:AL61)/SUM(Model_Baseline!AA60:AL60),0) -> 0.56627501 | D12: =IFERROR(SUM(Model_Aggressive!AA61:AL61)/SUM(Model_Aggressive!AA60:AL60),0) -> 0.65448953
A13: Non-Rx gross margin, year 3 | B13: =IFERROR(SUM(Model_Conservative!AA35:AL35)/SUM(Model_Conservative!AA31:AL31),0) -> 0.52529167 | C13: =IFERROR(SUM(Model_Baseline!AA35:AL35)/SUM(Model_Baseline!AA31:AL31),0) -> 0.60383109 | D13: =IFERROR(SUM(Model_Aggressive!AA35:AL35)/SUM(Model_Aggressive!AA31:AL31),0) -> 0.67252593
A14: Rx gross margin, year 3 | B14: =IFERROR(SUM(Model_Conservative!AA58:AL58)/SUM(Model_Conservative!AA51:AL51),0) -> 0.22279008 | C14: =IFERROR(SUM(Model_Baseline!AA58:AL58)/SUM(Model_Baseline!AA51:AL51),0) -> 0.4743331 | D14: =IFERROR(SUM(Model_Aggressive!AA58:AL58)/SUM(Model_Aggressive!AA51:AL51),0) -> 0.62914577
A16: EBITDA, year 1 | B16: =SUM(Model_Conservative!C76:N76) -> -484508.37 | C16: =SUM(Model_Baseline!C76:N76) -> -724853.68 | D16: =SUM(Model_Aggressive!C76:N76) -> 4502759.8
A17: EBITDA, year 2 | B17: =SUM(Model_Conservative!O76:Z76) -> -513822.89 | C17: =SUM(Model_Baseline!O76:Z76) -> -158810.55 | D17: =SUM(Model_Aggressive!O76:Z76) -> 23728727
A18: EBITDA, year 3 | B18: =SUM(Model_Conservative!AA76:AL76) -> -566047.37 | C18: =SUM(Model_Baseline!AA76:AL76) -> 298775.53 | D18: =SUM(Model_Aggressive!AA76:AL76) -> 54507760
A19: EBITDA margin, year 3 | B19: =IFERROR(SUM(Model_Conservative!AA76:AL76)/SUM(Model_Conservative!AA60:AL60),0) -> -1.6059268 | C19: =IFERROR(SUM(Model_Baseline!AA76:AL76)/SUM(Model_Baseline!AA60:AL60),0) -> 0.04230039 | D19: =IFERROR(SUM(Model_Aggressive!AA76:AL76)/SUM(Model_Aggressive!AA60:AL60),0) -> 0.39342028
A20: EBITDA, 36-month total | B20: =SUM(Model_Conservative!C76:AL76) -> -1564378.6 | C20: =SUM(Model_Baseline!C76:AL76) -> -584888.7 | D20: =SUM(Model_Aggressive!C76:AL76) -> 82739247
A22: First EBITDA-positive month | B22: =IF(MIN(Model_Conservative!C82:AL82)=999,"Not within 36 months",MIN(Model_Conservative!C82:AL82)) -> Not within 36 months | C22: =IF(MIN(Model_Baseline!C82:AL82)=999,"Not within 36 months",MIN(Model_Baseline!C82:AL82)) -> 22 | D22: =IF(MIN(Model_Aggressive!C82:AL82)=999,"Not within 36 months",MIN(Model_Aggressive!C82:AL82)) -> 3
A23: Peak cumulative cash deficit | B23: =MIN(0,MIN(Model_Conservative!C81:AL81)) -> -1587578.1 | C23: =MIN(0,MIN(Model_Baseline!C81:AL81)) -> -1095832.8 | D23: =MIN(0,MIN(Model_Aggressive!C81:AL81)) -> -724868.56
A24: Capital required (deficit plus 30% buffer) | B24: =-MIN(0,MIN(Model_Conservative!C81:AL81))*1.3 -> 2063851.6 | C24: =-MIN(0,MIN(Model_Baseline!C81:AL81))*1.3 -> 1424582.6 | D24: =-MIN(0,MIN(Model_Aggressive!C81:AL81))*1.3 -> 942329.13
A25: Cumulative cash at month 36 | B25: =Model_Conservative!AL81 -> -1587578.1 | C25: =Model_Baseline!AL81 -> -863023.6 | D25: =Model_Aggressive!AL81 -> 78769268
A27: Active subscribers at month 36 (non-Rx) | B27: =Model_Conservative!AL25 -> 351.37717 | C27: =Model_Baseline!AL25 -> 5810.4009 | D27: =Model_Aggressive!AL25 -> 92277.511
A28: Active programme members at month 36 (Rx) | B28: =Model_Conservative!AL45 -> 23.714637 | C28: =Model_Baseline!AL45 -> 837.56118 | D28: =Model_Aggressive!AL45 -> 19788.646
A29: Non-Rx share of year-3 net revenue | B29: =IFERROR(SUM(Model_Conservative!AA31:AL31)/SUM(Model_Conservative!AA60:AL60),0) -> 0.86502772 | C29: =IFERROR(SUM(Model_Baseline!AA31:AL31)/SUM(Model_Baseline!AA60:AL60),0) -> 0.70998716 | D29: =IFERROR(SUM(Model_Aggressive!AA31:AL31)/SUM(Model_Aggressive!AA60:AL60),0) -> 0.58422465
A31: Rx contribution per member-month | B31: =Model_Conservative!AL85 -> 41.92672 | C31: =Model_Baseline!AL85 -> 116.02563 | D31: =Model_Aggressive!AL85 -> 184.52661
A32: Rx gross LTV | B32: =Model_Conservative!AL86 -> 322.51323 | C32: =Model_Baseline!AL86 -> 1054.7785 | D32: =Model_Aggressive!AL86 -> 1942.3853
A33: Non-Rx contribution per order | B33: =Model_Conservative!AL87 -> 34.29104 | C33: =Model_Baseline!AL87 -> 45.68586 | D33: =Model_Aggressive!AL87 -> 57.880272
A34: Non-Rx subscriber gross LTV | B34: =Model_Conservative!AL88 -> 381.01156 | C34: =Model_Baseline!AL88 -> 652.65514 | D34: =Model_Aggressive!AL88 -> 1052.3686
A35: Blended CAC, year 3 average | B35: =IFERROR((SUM(Model_Conservative!AA15:AL15)-SUM(Model_Conservative!AA70:AL70))/SUM(Model_Conservative!AA83:AL83),0) -> 122.33752 | C35: =IFERROR((SUM(Model_Baseline!AA15:AL15)-SUM(Model_Baseline!AA70:AL70))/SUM(Model_Baseline!AA83:AL83),0) -> 109.30979 | D35: =IFERROR((SUM(Model_Aggressive!AA15:AL15)-SUM(Model_Aggressive!AA70:AL70))/SUM(Model_Aggressive!AA83:AL83),0) -> 125.76366
A36: Non-Rx LTV:CAC, year 3 | B36: =IFERROR(Model_Conservative!AL88/((SUM(Model_Conservative!AA15:AL15)-SUM(Model_Conservative!AA70:AL70))/SUM(Model_Conservative!AA83:AL83)),0) -> 3.1144293 | C36: =IFERROR(Model_Baseline!AL88/((SUM(Model_Baseline!AA15:AL15)-SUM(Model_Baseline!AA70:AL70))/SUM(Model_Baseline!AA83:AL83)),0) -> 5.9706927 | D36: =IFERROR(Model_Aggressive!AL88/((SUM(Model_Aggressive!AA15:AL15)-SUM(Model_Aggressive!AA70:AL70))/SUM(Model_Aggressive!AA83:AL83)),0) -> 8.3678274

Sheet Unit_Economics
A1: Unit economics: where the margin actually comes from
A2: Two separate businesses with very different shapes. The non-prescription line is a high-margin consumer product that can trade in all fifty states. The prescription line carries medication, clinician and cold-chain cost on every single fill, so its margin is structurally lower and its retention risk structurally higher.
A4: A. Non-prescription order (one shipment)
A5: Line item | B5: Conservative | C5: Baseline | D5: Aggressive
A6: Average order value | B6: =Assumptions!$D$31 -> 68 | C6: =Assumptions!$E$31 -> 78 | D6: =Assumptions!$F$31 -> 88
A7: less refunds and chargebacks | B7: =-Assumptions!$D$31*Assumptions!$D$61 -> -2.72 | C7: =-Assumptions!$E$31*Assumptions!$E$61 -> -2.34 | D7: =-Assumptions!$F$31*Assumptions!$F$61 -> -1.936
A8: Net revenue per order | B8: =B6+B7 -> 65.28 | C8: =C6+C7 -> 75.66 | D8: =D6+D7 -> 86.064
A9: less landed product COGS | B9: =-Assumptions!$D$31*Assumptions!$D$36 -> -20.4 | C9: =-Assumptions!$E$31*Assumptions!$E$36 -> -20.28 | D9: =-Assumptions!$F$31*Assumptions!$F$36 -> -19.36
A10: less pick, pack and ship | B10: =-Assumptions!$D$37 -> -8.5 | C10: =-Assumptions!$E$37 -> -7.5 | D10: =-Assumptions!$F$37 -> -6.5
A11: less payment processing | B11: =-B8*Assumptions!$D$60 -> -2.08896 | C11: =-C8*Assumptions!$E$60 -> -2.19414 | D11: =-D8*Assumptions!$F$60 -> -2.323728
A12: Contribution per order | B12: =B8+B9+B10+B11 -> 34.29104 | C12: =C8+C9+C10+C11 -> 45.68586 | D12: =D8+D9+D10+D11 -> 57.880272
A13: Contribution margin | B13: =IFERROR(B12/B8,0) -> 0.52529167 | C13: =IFERROR(C12/C8,0) -> 0.60383109 | D13: =IFERROR(D12/D8,0) -> 0.67252593
A14: Monthly subscription churn | B14: =Assumptions!$D$33 -> 0.09 | C14: =Assumptions!$E$33 -> 0.07 | D14: =Assumptions!$F$33 -> 0.055
A15: Implied subscriber life | B15: =1/Assumptions!$D$33 -> 11.111111 | C15: =1/Assumptions!$E$33 -> 14.285714 | D15: =1/Assumptions!$F$33 -> 18.181818
A16: Subscriber gross LTV | B16: =B12/Assumptions!$D$33 -> 381.01156 | C16: =C12/Assumptions!$E$33 -> 652.65514 | D16: =D12/Assumptions!$F$33 -> 1052.3686
A19: B. Prescription programme member (steady-state month)
A20: Line item | B20: Conservative | C20: Baseline | D20: Aggressive
A21: Programme price per member-month | B21: =Assumptions!$D$51 -> 199 | C21: =Assumptions!$E$51 -> 249 | D21: =Assumptions!$F$51 -> 299
A22: less refunds and chargebacks | B22: =-Assumptions!$D$51*Assumptions!$D$61 -> -7.96 | C22: =-Assumptions!$E$51*Assumptions!$E$61 -> -7.47 | D22: =-Assumptions!$F$51*Assumptions!$F$61 -> -6.578
A23: Net revenue per member-month | B23: =B21+B22 -> 191.04 | C23: =C21+C22 -> 241.53 | D23: =D21+D22 -> 292.422
A24: less pharmacy medication cost | B24: =-Assumptions!$D$54 -> -105 | C24: =-Assumptions!$E$54 -> -88 | D24: =-Assumptions!$F$54 -> -75
A25: less clinician monitoring and refill review | B25: =-Assumptions!$D$56 -> -10 | C25: =-Assumptions!$E$56 -> -8 | D25: =-Assumptions!$F$56 -> -6.5
A26: less cold-chain fulfilment and shipping | B26: =-Assumptions!$D$57 -> -22 | C26: =-Assumptions!$E$57 -> -18 | D26: =-Assumptions!$F$57 -> -15
A27: less non-clinical support | B27: =-Assumptions!$D$58 -> -6 | C27: =-Assumptions!$E$58 -> -4.5 | D27: =-Assumptions!$F$58 -> -3.5
A28: less payment processing | B28: =-B23*Assumptions!$D$60 -> -6.11328 | C28: =-C23*Assumptions!$E$60 -> -7.00437 | D28: =-D23*Assumptions!$F$60 -> -7.895394
A29: Contribution per member-month | B29: =B23+B24+B25+B26+B27+B28 -> 41.92672 | C29: =C23+C24+C25+C26+C27+C28 -> 116.02563 | D29: =D23+D24+D25+D26+D27+D28 -> 184.52661
A30: Contribution margin | B30: =IFERROR(B29/B23,0) -> 0.21946566 | C30: =IFERROR(C29/C23,0) -> 0.48037772 | D30: =IFERROR(D29/D23,0) -> 0.63102847
A31: Monthly churn | B31: =Assumptions!$D$49 -> 0.13 | C31: =Assumptions!$E$49 -> 0.11 | D31: =Assumptions!$F$49 -> 0.095
A32: Implied member life, months | B32: =1/Assumptions!$D$49 -> 7.6923077 | C32: =1/Assumptions!$E$49 -> 9.0909091 | D32: =1/Assumptions!$F$49 -> 10.526316
A33: Member gross LTV | B33: =B29/Assumptions!$D$49 -> 322.51323 | C33: =C29/Assumptions!$E$49 -> 1054.7785 | D33: =D29/Assumptions!$F$49 -> 1942.3853
A36: C. Prescription enrolment (one-time, at intake)
A37: Line item | B37: Conservative | C37: Baseline | D37: Aggressive
A38: Consultation fee charged | B38: =Assumptions!$D$52 -> 49 | C38: =Assumptions!$E$52 -> 59 | D38: =Assumptions!$F$52 -> 79
A39: less clinician cost per completed consult | B39: =-Assumptions!$D$55 -> -45 | C39: =-Assumptions!$E$55 -> -38 | D39: =-Assumptions!$F$55 -> -32
A40: Net on the consultation step | B40: =B38+B39 -> 4 | C40: =C38+C39 -> 21 | D40: =D38+D39 -> 47
A41: Consults per enrolled member (1 / enrolment rate) | B41: =1/Assumptions!$D$48 -> 1.7241379 | C41: =1/Assumptions!$E$48 -> 1.5151515 | D41: =1/Assumptions!$F$48 -> 1.4285714
A42: Consultation-step cost carried per enrolled member | B42: =B40*B41 -> 6.8965517 | C42: =C40*C41 -> 31.818182 | D42: =D40*D41 -> 67.142857
A45: D. What the flat $600/month provider fee changes, and what it does not
A46: The flat fee removes most FIXED operating cost from the model. It does not remove VARIABLE cost. Medication, per-consult clinician time, cold-chain shipping and card processing all scale with every order and every fill, and they are carried as separate drivers above.
A47: Published pricing for comparable turnkey telehealth infrastructure is $3,000-6,000 per month by tier, plus $5,000-10,000 onboarding, plus per-consult fees (benchmark B11). A $600 flat fee sits at roughly one fifth of the low end of that range.
...

Sheet Sensitivity
A1: Sensitivity: which assumptions actually decide the outcome
A2: Closed-form grids computed from the Baseline column of Assumptions, so they recalculate with the rest of the workbook rather than needing a what-if table. Change the Baseline inputs and these move.
A4: Grid 1. Prescription LTV:CAC by monthly churn and blended CAC
A5: Rx contribution per member-month (Baseline drivers) | D5: =Assumptions!$E$51*(1-Assumptions!$E$61)*(1-Assumptions!$E$60)-Assumptions!$E$54-Assumptions!$E$56-Assumptions!$E$57-Assumptions!$E$58 -> 116.02563
A6: Below 3.0x the programme does not pay for its own acquisition. Cells at or above 3.0x are viable.
A8: Monthly churn \ CAC | B8: 150 | C8: 250 | D8: 350 | E8: 450 | F8: 600 | G8: 800
A9: 0.08 | B9: =($D$5/$A9)/B$8 -> 9.6688025 | C9: =($D$5/$A9)/C$8 -> 5.8012815 | D9: =($D$5/$A9)/D$8 -> 4.1437725 | E9: =($D$5/$A9)/E$8 -> 3.2229342 | F9: =($D$5/$A9)/F$8 -> 2.4172006 | G9: =($D$5/$A9)/G$8 -> 1.8129005
A10: 0.095 | B10: =($D$5/$A10)/B$8 -> 8.1421495 | C10: =($D$5/$A10)/C$8 -> 4.8852897 | D10: =($D$5/$A10)/D$8 -> 3.4894926 | E10: =($D$5/$A10)/E$8 -> 2.7140498 | F10: =($D$5/$A10)/F$8 -> 2.0355374 | G10: =($D$5/$A10)/G$8 -> 1.526653
A11: 0.11 | B11: =($D$5/$A11)/B$8 -> 7.0318564 | C11: =($D$5/$A11)/C$8 -> 4.2191138 | D11: =($D$5/$A11)/D$8 -> 3.0136527 | E11: =($D$5/$A11)/E$8 -> 2.3439521 | F11: =($D$5/$A11)/F$8 -> 1.7579641 | G11: =($D$5/$A11)/G$8 -> 1.3184731
A12: 0.13 | B12: =($D$5/$A12)/B$8 -> 5.9500323 | C12: =($D$5/$A12)/C$8 -> 3.5700194 | D12: =($D$5/$A12)/D$8 -> 2.5500138 | E12: =($D$5/$A12)/E$8 -> 1.9833441 | F12: =($D$5/$A12)/F$8 -> 1.4875081 | G12: =($D$5/$A12)/G$8 -> 1.1156311
A13: 0.15 | B13: =($D$5/$A13)/B$8 -> 5.1566947 | C13: =($D$5/$A13)/C$8 -> 3.0940168 | D13: =($D$5/$A13)/D$8 -> 2.210012 | E13: =($D$5/$A13)/E$8 -> 1.7188982 | F13: =($D$5/$A13)/F$8 -> 1.2891737 | G13: =($D$5/$A13)/G$8 -> 0.96688025
A14: 0.18 | B14: =($D$5/$A14)/B$8 -> 4.2972456 | C14: =($D$5/$A14)/C$8 -> 2.5783473 | D14: =($D$5/$A14)/D$8 -> 1.8416767 | E14: =($D$5/$A14)/E$8 -> 1.4324152 | F14: =($D$5/$A14)/F$8 -> 1.0743114 | G14: =($D$5/$A14)/G$8 -> 0.80573354
A15: Baseline churn is 11.0%. Benchmark B17 puts real-world discontinuation near 65% at 12 months, which is roughly 8.4% monthly, and 84.4% at 24 months, roughly 7.4% monthly. Churn worse than about 15% monthly makes the prescription line unviable at any plausible CAC.
A18: Grid 2. Month-12 partner-driven sessions by reach per post and click-through
A19: These two drivers are the least evidenced in the model and they multiply, so the band they produce is wide by construction.
A21: Reach % \ CTR | B21: 0.002 | C21: 0.0035 | D21: 0.006 | E21: 0.009 | F21: 0.013
A22: 0.02 | B22: =Assumptions!$E$9*Assumptions!$E$10*$A22*B$21*(Assumptions!$E$14+(1-Assumptions!$E$14)*Assumptions!$E$13^(12-Assumptions!$E$6)) -> 1879.5062 | C22: =Assumptions!$E$9*Assumptions!$E$10*$A22*C$21*(Assumptions!$E$14+(1-Assumptions!$E$14)*Assumptions!$E$13^(12-Assumptions!$E$6)) -> 3289.1358 | D22: =Assumptions!$E$9*Assumptions!$E$10*$A22*D$21*(Assumptions!$E$14+(1-Assumptions!$E$14)*Assumptions!$E$13^(12-Assumptions!$E$6)) -> 5638.5186 | E22: =Assumptions!$E$9*Assumptions!$E$10*$A22*E$21*(Assumptions!$E$14+(1-Assumptions!$E$14)*Assumptions!$E$13^(12-Assumptions!$E$6)) -> 8457.7778 | F22: =Assumptions!$E$9*Assumptions!$E$10*$A22*F$21*(Assumptions!$E$14+(1-Assumptions!$E$14)*Assumptions!$E$13^(12-Assumptions!$E$6)) -> 12216.79
A23: 0.04 | B23: =Assumptions!$E$9*Assumptions!$E$10*$A23*B$21*(Assumptions!$E$14+(1-Assumptions!$E$14)*Assumptions!$E$13^(12-Assumptions!$E$6)) -> 3759.0124 | C23: =Assumptions!$E$9*Assumptions!$E$10*$A23*C$21*(Assumptions!$E$14+(1-Assumptions!$E$14)*Assumptions!$E$13^(12-Assumptions!$E$6)) -> 6578.2717 | D23: =Assumptions!$E$9*Assumptions!$E$10*$A23*D$21*(Assumptions!$E$14+(1-Assumptions!$E$14)*Assumptions!$E$13^(12-Assumptions!$E$6)) -> 11277.037 | E23: =Assumptions!$E$9*Assumptions!$E$10*$A23*E$21*(Assumptions!$E$14+(1-Assumptions!$E$14)*Assumptions!$E$13^(12-Assumptions!$E$6)) -> 16915.556 | F23: =Assumptions!$E$9*Assumptions!$E$10*$A23*F$21*(Assumptions!$E$14+(1-Assumptions!$E$14)*Assumptions!$E$13^(12-Assumptions!$E$6)) -> 24433.58
A24: 0.07 | B24: =Assumptions!$E$9*Assumptions!$E$10*$A24*B$21*(Assumptions!$E$14+(1-Assumptions!$E$14)*Assumptions!$E$13^(12-Assumptions!$E$6)) -> 6578.2717 | C24: =Assumptions!$E$9*Assumptions!$E$10*$A24*C$21*(Assumptions!$E$14+(1-Assumptions!$E$14)*Assumptions!$E$13^(12-Assumptions!$E$6)) -> 11511.975 | D24: =Assumptions!$E$9*Assumptions!$E$10*$A24*D$21*(Assumptions!$E$14+(1-Assumptions!$E$14)*Assumptions!$E$13^(12-Assumptions!$E$6)) -> 19734.815 | E24: =Assumptions!$E$9*Assumptions!$E$10*$A24*E$21*(Assumptions!$E$14+(1-Assumptions!$E$14)*Assumptions!$E$13^(12-Assumptions!$E$6)) -> 29602.222 | F24: =Assumptions!$E$9*Assumptions!$E$10*$A24*F$21*(Assumptions!$E$14+(1-Assumptions!$E$14)*Assumptions!$E$13^(12-Assumptions!$E$6)) -> 42758.766
A25: 0.11 | B25: =Assumptions!$E$9*Assumptions!$E$10*$A25*B$21*(Assumptions!$E$14+(1-Assumptions!$E$14)*Assumptions!$E$13^(12-Assumptions!$E$6)) -> 10337.284 | C25: =Assumptions!$E$9*Assumptions!$E$10*$A25*C$21*(Assumptions!$E$14+(1-Assumptions!$E$14)*Assumptions!$E$13^(12-Assumptions!$E$6)) -> 18090.247 | D25: =Assumptions!$E$9*Assumptions!$E$10*$A25*D$21*(Assumptions!$E$14+(1-Assumptions!$E$14)*Assumptions!$E$13^(12-Assumptions!$E$6)) -> 31011.852 | E25: =Assumptions!$E$9*Assumptions!$E$10*$A25*E$21*(Assumptions!$E$14+(1-Assumptions!$E$14)*Assumptions!$E$13^(12-Assumptions!$E$6)) -> 46517.778 | F25: =Assumptions!$E$9*Assumptions!$E$10*$A25*F$21*(Assumptions!$E$14+(1-Assumptions!$E$14)*Assumptions!$E$13^(12-Assumptions!$E$6)) -> 67192.346
A26: 0.15 | B26: =Assumptions!$E$9*Assumptions!$E$10*$A26*B$21*(Assumptions!$E$14+(1-Assumptions!$E$14)*Assumptions!$E$13^(12-Assumptions!$E$6)) -> 14096.296 | C26: =Assumptions!$E$9*Assumptions!$E$10*$A26*C$21*(Assumptions!$E$14+(1-Assumptions!$E$14)*Assumptions!$E$13^(12-Assumptions!$E$6)) -> 24668.519 | D26: =Assumptions!$E$9*Assumptions!$E$10*$A26*D$21*(Assumptions!$E$14+(1-Assumptions!$E$14)*Assumptions!$E$13^(12-Assumptions!$E$6)) -> 42288.889 | E26: =Assumptions!$E$9*Assumptions!$E$10*$A26*E$21*(Assumptions!$E$14+(1-Assumptions!$E$14)*Assumptions!$E$13^(12-Assumptions!$E$6)) -> 63433.334 | F26: =Assumptions!$E$9*Assumptions!$E$10*$A26*F$21*(Assumptions!$E$14+(1-Assumptions!$E$14)*Assumptions!$E$13^(12-Assumptions!$E$6)) -> 91625.927
A29: Grid 3. Year-3 blended gross margin by non-Rx COGS share and pharmacy cost per member-month
A30: Approximated at the Baseline year-3 revenue mix so the grid is readable. Non-Rx share of year-3 net revenue is taken from the Summary sheet.
A31: Non-Rx share of year-3 net revenue (Baseline) | E31: =Summary!C29 -> 0.70998716
A33: Non-Rx COGS % \ pharmacy $/mm | B33: 60 | C33: 75 | D33: 90 | E33: 105 | F33: 130
A34: 0.2 | B34: =$E$31*(1-$A34/(1-Assumptions!$E$61)-Assumptions!$E$37/(Assumptions!$E$31*(1-Assumptions!$E$61))-Assumptions!$E$60)+(1-$E$31)*(1-(B$33+Assumptions!$E$56+Assumptions!$E$57+Assumptions!$E$58)/(Assumptions!$E$51*(1-Assumptions!$E$61))-Assumptions!$E$60) -> 0.64556526 | C34: =$E$31*(1-$A34/(1-Assumptions!$E$61)-Assumptions!$E$37/(Assumptions!$E$31*(1-Assumptions!$E$61))-Assumptions!$E$60)+(1-$E$31)*(1-(C$33+Assumptions!$E$56+Assumptions!$E$57+Assumptions!$E$58)/(Assumptions!$E$51*(1-Assumptions!$E$61))-Assumptions!$E$60) -> 0.62755427 | D34: =$E$31*(1-$A34/(1-Assumptions!$E$61)-Assumptions!$E$37/(Assumptions!$E$31*(1-Assumptions!$E$61))-Assumptions!$E$60)+(1-$E$31)*(1-(D$33+Assumptions!$E$56+Assumptions!$E$57+Assumptions!$E$58)/(Assumptions!$E$51*(1-Assumptions!$E$61))-Assumptions!$E$60) -> 0.60954329 | E34: =$E$31*(1-$A34/(1-Assumptions!$E$61)-Assumptions!$E$37/(Assumptions!$E$31*(1-Assumptions!$E$61))-Assumptions!$E$60)+(1-$E$31)*(1-(E$33+Assumptions!$E$56+Assumptions!$E$57+Assumptions!$E$58)/(Assumptions!$E$51*(1-Assumptions!$E$61))-Assumptions!$E$60) -> 0.59153231 | F34: =$E$31*(1-$A34/(1-Assumptions!$E$61)-Assumptions!$E$37/(Assumptions!$E$31*(1-Assumptions!$E$61))-Assumptions!$E$60)+(1-$E$31)*(1-(F$33+Assumptions!$E$56+Assumptions!$E$57+Assumptions!$E$58)/(Assumptions!$E$51*(1-Assumptions!$E$61))-Assumptions!$E$60) -> 0.561514
A35: 0.24 | B35: =$E$31*(1-$A35/(1-Assumptions!$E$61)-Assumptions!$E$37/(Assumptions!$E$31*(1-Assumptions!$E$61))-Assumptions!$E$60)+(1-$E$31)*(1-(B$33+Assumptions!$E$56+Assumptions!$E$57+Assumptions!$E$58)/(Assumptions!$E$51*(1-Assumptions!$E$61))-Assumptions!$E$60) -> 0.61628744 | C35: =$E$31*(1-$A35/(1-Assumptions!$E$61)-Assumptions!$E$37/(Assumptions!$E$31*(1-Assumptions!$E$61))-Assumptions!$E$60)+(1-$E$31)*(1-(C$33+Assumptions!$E$56+Assumptions!$E$57+Assumptions!$E$58)/(Assumptions!$E$51*(1-Assumptions!$E$61))-Assumptions!$E$60) -> 0.59827645 | D35: =$E$31*(1-$A35/(1-Assumptions!$E$61)-Assumptions!$E$37/(Assumptions!$E$31*(1-Assumptions!$E$61))-Assumptions!$E$60)+(1-$E$31)*(1-(D$33+Assumptions!$E$56+Assumptions!$E$57+Assumptions!$E$58)/(Assumptions!$E$51*(1-Assumptions!$E$61))-Assumptions!$E$60) -> 0.58026547 | E35: =$E$31*(1-$A35/(1-Assumptions!$E$61)-Assumptions!$E$37/(Assumptions!$E$31*(1-Assumptions!$E$61))-Assumptions!$E$60)+(1-$E$31)*(1-(E$33+Assumptions!$E$56+Assumptions!$E$57+Assumptions!$E$58)/(Assumptions!$E$51*(1-Assumptions!$E$61))-Assumptions!$E$60) -> 0.56225449 | F35: =$E$31*(1-$A35/(1-Assumptions!$E$61)-Assumptions!$E$37/(Assumptions!$E$31*(1-Assumptions!$E$61))-Assumptions!$E$60)+(1-$E$31)*(1-(F$33+Assumptions!$E$56+Assumptions!$E$57+Assumptions!$E$58)/(Assumptions!$E$51*(1-Assumptions!$E$61))-Assumptions!$E$60) -> 0.53223618
A36: 0.28 | B36: =$E$31*(1-$A36/(1-Assumptions!$E$61)-Assumptions!$E$37/(Assumptions!$E$31*(1-Assumptions!$E$61))-Assumptions!$E$60)+(1-$E$31)*(1-(B$33+Assumptions!$E$56+Assumptions!$E$57+Assumptions!$E$58)/(Assumptions!$E$51*(1-Assumptions!$E$61))-Assumptions!$E$60) -> 0.58700961 | C36: =$E$31*(1-$A36/(1-Assumptions!$E$61)-Assumptions!$E$37/(Assumptions!$E$31*(1-Assumptions!$E$61))-Assumptions!$E$60)+(1-$E$31)*(1-(C$33+Assumptions!$E$56+Assumptions!$E$57+Assumptions!$E$58)/(Assumptions!$E$51*(1-Assumptions!$E$61))-Assumptions!$E$60) -> 0.56899863 | D36: =$E$31*(1-$A36/(1-Assumptions!$E$61)-Assumptions!$E$37/(Assumptions!$E$31*(1-Assumptions!$E$61))-Assumptions!$E$60)+(1-$E$31)*(1-(D$33+Assumptions!$E$56+Assumptions!$E$57+Assumptions!$E$58)/(Assumptions!$E$51*(1-Assumptions!$E$61))-Assumptions!$E$60) -> 0.55098765 | E36: =$E$31*(1-$A36/(1-Assumptions!$E$61)-Assumptions!$E$37/(Assumptions!$E$31*(1-Assumptions!$E$61))-Assumptions!$E$60)+(1-$E$31)*(1-(E$33+Assumptions!$E$56+Assumptions!$E$57+Assumptions!$E$58)/(Assumptions!$E$51*(1-Assumptions!$E$61))-Assumptions!$E$60) -> 0.53297667 | F36: =$E$31*(1-$A36/(1-Assumptions!$E$61)-Assumptions!$E$37/(Assumptions!$E$31*(1-Assumptions!$E$61))-Assumptions!$E$60)+(1-$E$31)*(1-(F$33+Assumptions!$E$56+Assumptions!$E$57+Assumptions!$E$58)/(Assumptions!$E$51*(1-Assumptions!$E$61))-Assumptions!$E$60) -> 0.50295836
A37: 0.32 | B37: =$E$31*(1-$A37/(1-Assumptions!$E$61)-Assumptions!$E$37/(Assumptions!$E$31*(1-Assumptions!$E$61))-Assumptions!$E$60)+(1-$E$31)*(1-(B$33+Assumptions!$E$56+Assumptions!$E$57+Assumptions!$E$58)/(Assumptions!$E$51*(1-Assumptions!$E$61))-Assumptions!$E$60) -> 0.55773179 | C37: =$E$31*(1-$A37/(1-Assumptions!$E$61)-Assumptions!$E$37/(Assumptions!$E$31*(1-Assumptions!$E$61))-Assumptions!$E$60)+(1-$E$31)*(1-(C$33+Assumptions!$E$56+Assumptions!$E$57+Assumptions!$E$58)/(Assumptions!$E$51*(1-Assumptions!$E$61))-Assumptions!$E$60) -> 0.53972081 | D37: =$E$31*(1-$A37/(1-Assumptions!$E$61)-Assumptions!$E$37/(Assumptions!$E$31*(1-Assumptions!$E$61))-Assumptions!$E$60)+(1-$E$31)*(1-(D$33+Assumptions!$E$56+Assumptions!$E$57+Assumptions!$E$58)/(Assumptions!$E$51*(1-Assumptions!$E$61))-Assumptions!$E$60) -> 0.52170983 | E37: =$E$31*(1-$A37/(1-Assumptions!$E$61)-Assumptions!$E$37/(Assumptions!$E$31*(1-Assumptions!$E$61))-Assumptions!$E$60)+(1-$E$31)*(1-(E$33+Assumptions!$E$56+Assumptions!$E$57+Assumptions!$E$58)/(Assumptions!$E$51*(1-Assumptions!$E$61))-Assumptions!$E$60) -> 0.50369885 | F37: =$E$31*(1-$A37/(1-Assumptions!$E$61)-Assumptions!$E$37/(Assumptions!$E$31*(1-Assumptions!$E$61))-Assumptions!$E$60)+(1-$E$31)*(1-(F$33+Assumptions!$E$56+Assumptions!$E$57+Assumptions!$E$58)/(Assumptions!$E$51*(1-Assumptions!$E$61))-Assumptions!$E$60) -> 0.47368054
A38: 0.38 | B38: =$E$31*(1-$A38/(1-Assumptions!$E$61)-Assumptions!$E$37/(Assumptions!$E$31*(1-Assumptions!$E$61))-Assumptions!$E$60)+(1-$E$31)*(1-(B$33+Assumptions!$E$56+Assumptions!$E$57+Assumptions!$E$58)/(Assumptions!$E$51*(1-Assumptions!$E$61))-Assumptions!$E$60) -> 0.51381506 | C38: =$E$31*(1-$A38/(1-Assumptions!$E$61)-Assumptions!$E$37/(Assumptions!$E$31*(1-Assumptions!$E$61))-Assumptions!$E$60)+(1-$E$31)*(1-(C$33+Assumptions!$E$56+Assumptions!$E$57+Assumptions!$E$58)/(Assumptions!$E$51*(1-Assumptions!$E$61))-Assumptions!$E$60) -> 0.49580408 | D38: =$E$31*(1-$A38/(1-Assumptions!$E$61)-Assumptions!$E$37/(Assumptions!$E$31*(1-Assumptions!$E$61))-Assumptions!$E$60)+(1-$E$31)*(1-(D$33+Assumptions!$E$56+Assumptions!$E$57+Assumptions!$E$58)/(Assumptions!$E$51*(1-Assumptions!$E$61))-Assumptions!$E$60) -> 0.4777931 | E38: =$E$31*(1-$A38/(1-Assumptions!$E$61)-Assumptions!$E$37/(Assumptions!$E$31*(1-Assumptions!$E$61))-Assumptions!$E$60)+(1-$E$31)*(1-(E$33+Assumptions!$E$56+Assumptions!$E$57+Assumptions!$E$58)/(Assumptions!$E$51*(1-Assumptions!$E$61))-Assumptions!$E$60) -> 0.45978211 | F38: =$E$31*(1-$A38/(1-Assumptions!$E$61)-Assumptions!$E$37/(Assumptions!$E$31*(1-Assumptions!$E$61))-Assumptions!$E$60)+(1-$E$31)*(1-(F$33+Assumptions!$E$56+Assumptions!$E$57+Assumptions!$E$58)/(Assumptions!$E$51*(1-Assumptions!$E$61))-Assumptions!$E$60) -> 0.42976381

Sheet Partner_Economics
A1: Proposed brand-partner economics - illustrative only
A2: No terms have been offered, negotiated or accepted. Nothing on this sheet is an offer. The structure below exists so the conversation can start from arithmetic instead of adjectives. The equity figures use an illustrative revenue multiple and are NOT a valuation; a valuation requires an actual process.
A4: Illustrative revenue multiple on year-3 net revenue | C4: 3 | D4: Editable. DTC and telehealth multiples move with growth, margin and rate cycles; 2-5x net revenue is a commonly quoted range for profitable consumer health at scale. Not a valuation.
A6: Item | B6: Conservative | C6: Baseline | D6: Aggressive
A7: Cash retainer over 36 months | B7: =-SUM(Model_Conservative!C73:AL73) -> 0 | C7: =-SUM(Model_Baseline!C73:AL73) -> 525000 | D7: =-SUM(Model_Aggressive!C73:AL73) -> 875000
A8: Royalty over 36 months | B8: =-SUM(Model_Conservative!C74:AL74) -> 36244.035 | C8: =-SUM(Model_Baseline!C74:AL74) -> 648520.93 | D8: =-SUM(Model_Aggressive!C74:AL74) -> 10833981
A9: Total cash to partner over 36 months | B9: =B7+B8 -> 36244.035 | C9: =C7+C8 -> 1173520.9 | D9: =D7+D8 -> 11708981
A10: Royalty in year 3 alone | B10: =-SUM(Model_Conservative!AA74:AL74) -> 17623.698 | C10: =-SUM(Model_Baseline!AA74:AL74) -> 353159.31 | D10: =-SUM(Model_Aggressive!AA74:AL74) -> 6927421.3
A11: Partner equity, fully diluted | B11: =Assumptions!$D$78 -> 0.1 | C11: =Assumptions!$E$78 -> 0.15 | D11: =Assumptions!$F$78 -> 0.2
A12: Illustrative equity value at year-3 revenue multiple | B12: =Summary!B7*$C$4*B11 -> 105742.19 | C12: =Summary!C7*$C$4*C11 -> 3178433.8 | D12: =Summary!D7*$C$4*D11 -> 83129056
A13: Total illustrative 36-month partner value | B13: =B9+B12 -> 141986.22 | C13: =C9+C12 -> 4351954.7 | D13: =D9+D12 -> 94838037
A14: Partner cash as a share of 36-month net revenue | B14: =IFERROR(B9/Summary!B8,0) -> 0.05 | C14: =IFERROR(C9/Summary!C8,0) -> 0.09047672 | D14: =IFERROR(D9/Summary!D8,0) -> 0.05403822
A16: Constraints that shape any deal here
A17: The partner can promote the brand and the non-prescription line. The partner should not promote specific compounded prescription drugs. 503A compounders operate under advertising and promotion limits, prescription-drug advertising carries its own disclosure requirements, and celebrity promotion of a prescription product invites exactly the scrutiny a new brand cannot absorb. Separating what is promotable from what is prescribable is a design requirement, not a preference.
A18: Every paid or equity-holding endorsement needs a clear and conspicuous disclosure of the material connection, on every post and in every format, under the FTC Endorsement Guides. A founder's equity stake is a material connection. Earlier research in this project found the proposed partner named on the FTC's September 2017 list of influencers sent warning letters about undisclosed endorsements, which makes disclosure discipline a specific and personal risk here rather than a generic one.
A19: Compensation to the medical entity and to clinicians must never vary with prescription volume, programme enrolments or revenue. Partner compensation may be tied to revenue; clinical compensation may not. Keeping those two facts in separate contracts is the point of the structure.
A20: A prior or concurrent promotion of a competing weight-management or GLP-1 product may create a category-exclusivity conflict. Earlier research in this project flagged a possible prior GLP-1-adjacent promotion; brand and paid status were not verified. Resolve it in diligence before any announcement.
A21: Nothing here is an offer, and nothing here should be shared as though terms exist. Until definitive agreements are signed the brand is a proposed concept and the partner's role is proposed.

Sheet Provider_Diligence
A1: Turnkey provider at $600/month - what to confirm before signing
A2: The whole model rests on this vendor. At this fee the vendor carries no volume risk, so scope has to be contractual. Every row is a question to put in writing; the Why column says what breaks in the model if the answer is not what you expect.
A4: # | B4: Question to put in writing | C4: Why it matters to the model | D4: Status
A5: 1 | B5: Does the $600 include per-consult clinician fees, or are those billed separately per visit? | C5: The model assumes separately, at $32-45 per completed consult. If included, Rx gross margin improves by roughly the consult cost divided by enrolments. If excluded and higher than assumed, enrolment economics compress. | D5: Open
A6: 2 | B6: Does the $600 include medication cost, or does the pharmacy bill per fill? | C6: The model assumes the pharmacy bills per fill at $75-105 per member-month. This is the largest single variable cost in the Rx line; a written tiered schedule is essential. | D6: Open
A7: 3 | B7: Does the $600 include cold-chain shipping and packaging, or is that billed per shipment? | C7: The model assumes per shipment at $15-22. Benchmark B09 shows a $1.95 pack rate is only the pack step, not the landed temperature-controlled cost. | D7: Open
A8: 4 | B8: Is payment processing inside the fee, and at what rate and risk classification? | C8: The model carries 2.7-3.2% separately. Healthcare and supplement merchants are frequently underwritten as elevated risk. | D8: Open
A9: 5 | B9: Which specific pharmacies fulfil, under which licences, and in which states? | C9: Drives the state-coverage ramp, which is the gate on the whole Rx funnel. Name the pharmacies; do not accept a count. | D9: Open
A10: 6 | B10: For each pharmacy: 503A, 503B, or both, and which is used for which product? | C10: 503A compounds pursuant to individual patient prescriptions. 503B outsourcing facilities are built for non-patient-specific office stock. They are not interchangeable for a consumer-direct model, and assuming they are is a common and expensive error. | D10: Open
A11: 7 | B11: How does the arrangement handle interstate distribution limits for 503A pharmacies? | C11: Section 503A(b)(3) caps interstate distribution of compounded drugs at 5% of total prescription orders unless the pharmacy's state has signed the FDA memorandum of understanding. FDA's compounding MOU index currently lists only three MOUs, all suspended, and FDA has repeatedly deferred enforcement of the 5% limit pending rulemaking. Deferred enforcement is discretionary and revocable, so a national single-pharmacy Rx model is a policy bet, not a settled structure. | D11: Open
A12: 8 | B12: Which peptides are on the current FDA 503A Category 1 bulks list, as of the signing date? | C12: Determines the formulary. Benchmark B18: FDA removed 12 peptides from Category 2 in April 2026, the PCAC met in July 2026 on three more and will meet again before the end of February 2027 on five others. The list moves; the contract should require the provider to track it. | D12: Open
A13: 9 | B13: Is any product 'essentially a copy' of an approved drug? | C13: Section 503A limits compounding of drugs that are essentially copies of commercially available products. This is where compounded-GLP-1 programmes have drawn enforcement. | D13: Open
A14: 10 | B14: Who holds the LegitScript healthcare merchant certification, and for which website? | C14: Certification is site-specific and gates healthcare advertising across Google, Meta, Microsoft and TikTok. If it is the provider's certification on the provider's domain, the brand's own site may not be covered. No certification means no scaled paid acquisition, which removes most of the paid-traffic line from the model. | D14: Open
A15: 11 | B15: What is the legal structure: MSO and friendly-PC, and who owns the physician entity? | C15: Corporate-practice-of-medicine rules in many states bar a non-physician company from owning a medical practice or splitting professional fees. Get the structure opinion, not a reassurance. | D15: Open
A16: 12 | B16: How are clinicians compensated, and does any element vary with prescribing or revenue? | C16: Any volume- or revenue-linked clinical compensation is a fee-splitting and kickback problem and undermines the clinical-independence position the whole model depends on. | D16: Open
... A24: 20 | B24: Auto-renewal mechanics: consent capture, renewal reminders, cancellation path, and who is liable? | C24: ROSCA and state auto-renewal laws are the most common source of consumer-protection claims in subscription health. The cancellation path must be as easy as the sign-up path, and the brand is liable for it whoever built it. | D24: Open

Sheet Benchmarks
A1: Benchmarks behind the drivers
A2: Third-party unless marked as an analyst assumption. Figures were taken from search-result summaries during a session in which direct page loads were restricted; load-bearing figures were corroborated across two independent queries. Ranges are ranges, not measurements.
A4: ID | B4: Topic | C4: Finding | D4: How it is used | E4: Confidence | F4: Sources
A5: B01 | B5: Public telehealth gross margin (closest listed comparable) | C5: Hims & Hers gross margin 74% FY2025 vs 79% FY2024; 65% in Q1 2026 and 63.8% in Q2 2026. Decline attributed to weight-loss offerings with shorter shipping cadences and higher fulfilment costs, plus international mix. | D5: Ceiling reference for a telehealth blended gross margin. Reserve Clinic's Rx line is modelled well below this because it carries cold-chain shipping on every fill. | E5: High (company-reported) | F5: https://investors.hims.com/news/news-details/2026/Hims--Hers-Health-Inc--Reports-Fourth-Quarter-and-Full-Year-2025-Financial-Results/default.aspx https://www.sec.gov/Archives/edgar/data/1773751/000177375126000022/hims-20251231.htm
A6: B02 | B6: Telehealth marketing intensity | C6: Hims & Hers marketing expense was ~40% of revenue in Q2 2025 (down from ~46% a year earlier) and ~34.8% of revenue in Q2 2026 ($262.2M on $753.2M). | D6: Anchors the paid-media-as-percent-of-revenue driver (25-32% by scenario). A celebrity-led brand should sit below this, not above, or the audience is not doing any work. | E6: High (company-reported) | F6: https://www.sec.gov/Archives/edgar/data/0001773751/000177375126000161/hims-20260630x8xkearningsr.htm https://finance.yahoo.com/markets/stocks/articles/hims-hers-stock-plunges-post-171900613.html
A7: B03 | B7: DTC supplement gross margin and landed COGS | C7: Landed COGS (materials, packaging, manufacturing, inbound freight, duties) typically 20-30% of retail for a DTC supplement, producing 70-80% gross margin. Target range cited as 60-80%. Public DTC median gross margin ~57% for non-food categories. Per-unit COGS $3-15 depending on dosage form and volume. | D7: Non-Rx line COGS driver set at 22-30% of retail. | E7: Medium (aggregator/advisory sources, not audited) | F7: https://eightx.co/blog/supplements-brand-unit-economics https://commercecatalyst.ai/benchmarks/supplements/ https://eightx.co/blog/average-dtc-gross-margin-public-companies https://inventoryready.com/guides/supplement-pricing-strategy
A8: B04 | B8: DTC supplement CAC | C8: CAC $45-80 for supplements per triangulated industry estimates; $53-91 across ecommerce categories generally. | D8: Sanity band for the computed blended CAC output. The model derives CAC rather than assuming it. | E8: Medium | F8: https://commercecatalyst.ai/benchmarks/supplements/ https://foundrycro.com/blog/dtc-supplements-marketing-benchmarks-2026/
A9: B05 | B9: Supplement subscription churn | C9: 4-7% monthly when well run; 8-12% at health-and-wellness category average; 12-20% of subscribers churn in month 1 alone. Below 5% strong, below 4% top-tier, sustained above 10% a retention emergency. | D9: Non-Rx subscription churn driver 5.5-9% monthly by scenario. | E9: Medium | F9: https://eightx.co/blog/supplement-subscription-churn-rate-benchmark https://eightx.co/blog/average-subscription-churn-rate-by-category https://eightx.co/blog/supplements-subscription-economics
A10: B06 | B10: Supplement AOV, LTV and LTV:CAC | C10: AOV $30-65 monthly with 12-month LTV $300-600 (Recharge benchmarks cited). At 8% monthly churn a $40 subscriber at 55% margin returns ~$275 LTV. Healthy LTV:CAC 3.5:1 to 6:1, with 3:1 the floor. | D10: Non-Rx AOV driver $68-88 (premium positioning above the cited band) and the 3.0x LTV:CAC gate. | E10: Medium | F10: https://eightx.co/blog/supplements-subscription-economics https://www.retentionlab.ai/blog/good-ltv-dtc-benchmarks-2026 https://commercecatalyst.ai/benchmarks/supplements/
A11: B07 | B11: Compounded peptide programme pricing, US, 2026 | C11: Sermorelin $96-199/mo via telehealth, $200-400/mo in-clinic. BPC-157 or TB-500 tissue protocols $100-300/mo. CJC-1295/ipamorelin stack $80-180/mo. Sermorelin plus CJC-1295 combination protocols $350-600/mo. | D11: Rx programme price driver $199-299 per member-month, blended across protocols. | E11: Medium (marketing pages and category guides, not a price survey) | F11: https://healingmaps.com/sermorelin-cost-guide/ https://peptidenewsdigest.org/pricing/peptides/ https://www.peptidemark.com/news/peptide-therapy-cost-breakdown-2026 https://healingmaps.com/peptide-telehealth/
A12: B08 | B12: Asynchronous consult cost and price | C12: Asynchronous e-visits price at roughly $15-40 to the patient; raw median prices $20 (5-10 min) to $60 (21+ min). From the operator side a cited COGS breakdown is provider time $30, platform $10, support $10 per ongoing-care programme. Synchronous video $50-100. | D12: Clinician cost per completed consult driver $32-45, and consult fee charged $49-79. | E12: Medium | F12: https://bask.health/blog/pricing-for-telemedicine-services https://www.ncbi.nlm.nih.gov/books/NBK459384/ https://openmypro.com/cost/telehealth-visit-cost
A13: B09 | B13: Cold-chain fulfilment cost for peptides | C13: Quoted base pack rate $1.95 per order plus $350/month cold storage for refrigerated peptide inventory; FedEx 2-Day temperature-controlled is the standard lane. Additional cost for insulated mailers, gel packs, refrigerated carrier surcharges. Most peptides require 2-8 C. | D13: Cold-chain shipping driver $15-22 per Rx fill, which is the pack rate plus the expedited insulated lane, not the pack rate alone. | E13: Medium (vendor marketing pages) | F13: https://rapidfulfillment.com/blogs/news/peptide-fulfillment-pricing https://3plguys.com/articles/peptide-shipping-guide https://amzprep.com/peptide-fulfilment-services/
A14: B10 | B14: LegitScript healthcare merchant certification cost | C14: 2025-2026 schedule cited as $975 application plus $2,150 annual per website; ~$3,125 year one for a single-site brand, ~$2,150/yr ongoing; expedited review ~$2,500 extra. It gates healthcare advertising on Google, Meta, Microsoft, TikTok, LinkedIn and Nextdoor, and is close to a prerequisite for card-not-present acceptance. | D14: Certification line in opex. Also a gating dependency for the paid-media plan: no certification, no paid healthcare advertising at scale. | E14: Medium (third-party summaries of a schedule that changes; confirm live) | F14: https://myorbithealth.com/blog/legitscript-certification-telehealth-guide https://www.legitscript.com/certification/healthcare-certification/ https://www.2accept.net/blog/legitscript-certification-cost
A15: B11 | B15: Market rate for turnkey white-label telehealth infrastructure | C15: One vendor's published pricing is $3,000-6,000 per month by plan tier plus a $5,000-10,000 one-time onboarding fee and separate per-consult fees, as of mid-2026. Other vendors advertise a flat monthly fee with zero revenue share including LegitScript and multi-pharmacy access; most gate pricing behind a demo. The category supplies licensed providers, HIPAA intake and EMR, e-prescribing, pharmacy fulfilment and the MSO / friendly-PC legal structure while the brand owns the customer. | D15: Directly relevant to the stated $600/month flat fee. The model treats $600 as a platform/SaaS fee only and carries per-consult, medication, shipping and processing costs separately, because a fee at one fifth of the low end of published market pricing is very unlikely to absorb per-unit variable costs. | E15: Medium | F15: https://myorbithealth.com/blog/best-white-label-telehealth-platforms https://cuvo.co/blog/best-white-label-telehealth-platforms https://pharmabro.co/ https://thepharmacyhub.com/telehealth/ https://whitelabelmd.com/
... A22: B18 | B22: 503A bulk substances list movement on peptides, 2026 | C22: On 15 April 2026 FDA removed 12 peptides from Category 2 of the 503A bulk drug substances list. First-batch substances under review include BPC-157, KPV, MOTS-c, Emideltide (DSIP), Epitalon, Semax and TB-500. The Pharmacy Compounding Advisory Committee met 23-24 July 2026 on Emideltide, Semax and Epitalon related substances, and FDA announced a further meeting before the end of February 2027 covering GHK-Cu, Melanotan II, Cathelicidin (LL-37), Dihexa acetate and PEG-MGF. Gonadorelin acetate has been added to Category 1. One category guide states CJC-1295 and ipamorelin 'returned to Category 1 in 2026'. | D22: Not a financial driver but the gate on which products the Rx line may legally carry. The formulary must be re-verified against the live FDA list before launch and re-verified on each PCAC action; the CJC-1295/ipamorelin claim in particular rests on a single secondary source and is NOT treated as established. | E22: Medium for the FDA actions, Low for the CJC-1295/ipamorelin Category 1 claim | F22: https://www.fda.gov/advisory-committees/advisory-committee-calendar/july-23-24-2026-meeting-pharmacy-compounding-advisory-committee-07232026 https://www.thefdalawblog.com/2026/04/fdas-peptide-rally-what-compounders-and-industry-need-to-know-post-1-of-2/ https://www.fagronacademy.us/blog/industry-update-503a-and-503b-bulks-lists-new-revisions
A24: Not retrievable in this environment
B25: First-party analytics for any competitor (sessions, conversion rate, CAC, churn) — no traffic tool or ad library was reachable.
B26: Audited financials for any private peptide or celebrity supplement brand. IM8 and Gruns revenue figures are self-reported via press.
B27: Scott Disick's audience composition (US share, age, gender, health-category affinity) and any historical conversion performance on a paid endorsement.
B28: The identity, licences, contract terms, insurance, pharmacy network and LegitScript status of the $600/month provider — no provider was named.

Sheet Model_Conservative
A1: Reserve Clinic - Conservative scenario, months 1-36
A2: Every cell is a formula. Inputs live on Assumptions only. Green = link to Assumptions.
A4: Line | B4: Unit | C4: M1 | D4: M2 | E4: M3 | F4: M4 | G4: M5 | H4: M6 | I4: M7 | J4: M8 | K4: M9 | L4: M10 | M4: M11 | N4: M12 | O4: M13 | P4: M14 | Q4: M15 | R4: M16 | S4: M17 | T4: M18 | U4: M19 | V4: M20 | W4: M21 | X4: M22 | Y4: M23 | Z4: M24 | AA4: M25 | AB4: M26 | AC4: M27 | AD4: M28 | AE4: M29 | AF4: M30 | AG4: M31 | AH4: M32 | AI4: M33 | AJ4: M34 | AK4: M35 | AL4: M36 | AM4: Total / final
A5: Month index | B5: # | C5: 1 | D5: 2 | E5: 3 | F5: 4 | G5: 5 | H5: 6 | I5: 7 | J5: 8 | K5: 9 | L5: 10 | M5: 11 | N5: 12 | O5: 13 | P5: 14 | Q5: 15 | R5: 16 | S5: 17 | T5: 18 | U5: 19 | V5: 20 | W5: 21 | X5: 22 | Y5: 23 | Z5: 24 | AA5: 25 | AB5: 26 | AC5: 27 | AD5: 28 | AE5: 29 | AF5: 30 | AG5: 31 | AH5: 32 | AI5: 33 | AJ5: 34 | AK5: 35 | AL5: 36
A6: Year | B6: # | C6: =ROUNDUP(C$5/12,0) -> 1 | D6: =ROUNDUP(D$5/12,0) -> 1 | E6: =ROUNDUP(E$5/12,0) -> 1 | F6: =ROUNDUP(F$5/12,0) -> 1 | G6: =ROUNDUP(G$5/12,0) -> 1 | H6: =ROUNDUP(H$5/12,0) -> 1 | I6: =ROUNDUP(I$5/12,0) -> 1 | J6: =ROUNDUP(J$5/12,0) -> 1 | ... AL6: =ROUNDUP(AL$5/12,0) -> 3
A8: Non-Rx line live (1/0) | B8: flag | C8: =IF(C$5>=Assumptions!$D$6,1,0) -> 0 | D8: =IF(D$5>=Assumptions!$D$6,1,0) -> 0 | E8: =IF(E$5>=Assumptions!$D$6,1,0) -> 1 | F8: =IF(F$5>=Assumptions!$D$6,1,0) -> 1 | G8: =IF(G$5>=Assumptions!$D$6,1,0) -> 1 | H8: =IF(H$5>=Assumptions!$D$6,1,0) -> 1 | I8: =IF(I$5>=Assumptions!$D$6,1,0) -> 1 | J8: =IF(J$5>=Assumptions!$D$6,1,0) -> 1 | ... AL8: =IF(AL$5>=Assumptions!$D$6,1,0) -> 1
A9: Rx line live (1/0) | B9: flag | C9: =IF(C$5>=Assumptions!$D$7,1,0) -> 0 | D9: =IF(D$5>=Assumptions!$D$7,1,0) -> 0 | E9: =IF(E$5>=Assumptions!$D$7,1,0) -> 0 | F9: =IF(F$5>=Assumptions!$D$7,1,0) -> 0 | G9: =IF(G$5>=Assumptions!$D$7,1,0) -> 0 | H9: =IF(H$5>=Assumptions!$D$7,1,0) -> 0 | I9: =IF(I$5>=Assumptions!$D$7,1,0) -> 0 | J9: =IF(J$5>=Assumptions!$D$7,1,0) -> 0 | ... AL9: =IF(AL$5>=Assumptions!$D$7,1,0) -> 1
A10: Months since non-Rx launch | B10: # | C10: =MAX(0,C$5-Assumptions!$D$6) -> 0 | D10: =MAX(0,D$5-Assumptions!$D$6) -> 0 | E10: =MAX(0,E$5-Assumptions!$D$6) -> 0 | F10: =MAX(0,F$5-Assumptions!$D$6) -> 1 | G10: =MAX(0,G$5-Assumptions!$D$6) -> 2 | H10: =MAX(0,H$5-Assumptions!$D$6) -> 3 | I10: =MAX(0,I$5-Assumptions!$D$6) -> 4 | J10: =MAX(0,J$5-Assumptions!$D$6) -> 5 | ... AL10: =MAX(0,AL$5-Assumptions!$D$6) -> 33
